Workbook

Sheet 仕入先マスタ
A1: 仕入先コード | B1: 仕入先名 | C1: 住所１ | D1: 住所２ | E1: 電話番号 | F1: 担当者 | G1: 支払条件 | H1: 仕入先見積税区分 | I1: 紹介文 | J1: 備考
A2: NKH | B2: NIKI HILLS
A3: NAO | B3: Nao-buns
A4: NNS | B4: にんにく種蔵 | C4: 〒060-0062 | D4: 北海道札幌市中央区南２条西１丁目５−６ 第2広和ビル | E4: 090-2035-0229 | F4: 佐藤 | G4: 月末締翌月末払い | H4: 内税 | I4: 北海道初のにんにく専門セレクトショップ。自社農園のダイヤモンドにんにくをはじめ、全国より厳選したにんにく商品を取り扱うにんにく専門店です。
A5: HNM | B5: ほんま
A6: SZS | B6: サザエ食品
A7: JEN | B7: ジョーエンタープライズ
A8: TKP | B8: トカプコーヒー
A9: HRK | B9: ハリカ
A10: VGW | B10: ベジタブルワークス
A11: MTY | B11: マルトシ吉野商店
A12: IHS | B12: 井原水産
A13: HBJ | B13: 北海道美女物語
A14: HOY | B14: 北王よいち
A15: OKK | B15: 小樽かね丁鍛冶
A16: YSS | B16: 山下水産
... A37: NVP | B37: ニセコビュープラザ
A38: HAK | B38: 北見ハッカ通商 | C38: 〒090-0056 | D38: 北海道北見市卸町1丁目7-3 | E38: 0157-66-5655 | F38: 吉田 | G38: 前金 | I38: 「北のかおり ハッカ油」でおなじみ、北見ハッカ通商です。紀元前から人々の生活に計り知れない役割を果たしてきた「天然ハッカ」は、かつて世界シェアの70％以上を北見地方で生産していた時代がありました。 この古き良き「ハッカ隆盛時代」の後、時代の変化とともに世界に誇った「ホクレン北見薄荷工場」も閉鎖。すっかり影を潜めてしまった「北見の天然ハッカ」を、今私たち北見ハッカ通商が復元しています。
A39: CSG | B39: CHISE GARDEN | C39: 〒048-1542 | D39: 北海道虻田郡ニセコ町字近藤８１７ | E39: 090-1302-4156 | F39: 平手千津子 | G39: 月末締翌月末払い | I39: 北海道ニセコ町にてワインぶどう無農薬、無化学肥料で野菜やベリーを生産加工販売しています 山野草・宿根草を中心としたガーデンづくりに奮闘中です！
A40: HAD | B40: 白亜ダイシン | C40: 〒068-0833 | D40: 北海道岩見沢市志文町292-4 | E40: 0120-70-6003 | I40: ノースファームストックには「北海道のおいしいものを蔵出しで」、という思いが込められています。自分たちの目の届く範囲で産地や生産者とつながり、良質な素材をすべて手づくりするのが基本。原点を守ることで、北海道のぬくもりや、やさしさもお伝えしたいのです。また、その思いから商品名に「北海道」を冠しています。
A41: SKA | B41: シャルキュトリーアカイシ | C41: 〒048-1551 | D41: 北海道虻田郡ニセコ町字里見11-26 | E41: 0136-55-5575 | F41: 赤石 | G41: 月末締翌月末払い | I41: 北海道ニセコならではのシャルキュトリーを生み出すため、 2018年シャルキュトリーアカイシを起業。 素材の持つ美味しさを引き出し、北海道の風土を活かしたものづくりを目指す。
A42: FSS | B42: 藤田水産 | C42: 〒078-3454 | D42: 北海道留萌郡小平町字鬼鹿広富90番地 | E42: 0164-57-1048 | F42: 藤田貢 | G42: 月末締翌月末払い | I42: タコを主に、イカ、鮭の珍味類を生産している。珍味の藤田水産の地名度アップに大きな役割を果たした「一杯だこ」は昭和38年先代のアイデアで製品化された息の長い逸品。当時棒くん（たこ足の丸ごとの燻製品）にならない小さいタコに着目、タコの姿そのまま燻製に仕上げた。
A43: YTS | B43: 谷田製菓 | C43: 〒069-1521 | D43: 北海道夕張郡栗山町錦３丁目１３４ | E43: 0123-72-1234 | F43: 木村 | G43: 月末締翌月末払い | I43: 日本一きびだんご大正１２年創製 令和５年生誕１００年を迎えます。北海道開拓の精神と関東大震災の復興を願い、起備団合の名称で発売
A44: SBR | B44: 北海道食美樂
A45: UST | B45: 上田精肉店
A46: HEF | B46: 北海道エゾシカファクトリー
A47: SEF | B47: 知床エゾシカファーム
A48: NRS | B48: ナチュラルシー
A49: ESF | B49: 東しゃこたん漁協
A50: STF | B50: 佐藤水産
A51: CCL | B51: コットンクラブ
A52: YMT | B52: ヤマト運輸
A53: BTD | B53: ベターデイズ | C53: 〒003-0029 | D53: 北海道札幌市白石区平和通二丁目北３番３０号 | E53: 090-1526-6097 | F53: 飯塚 忠志 | G53: 月末締翌月末払い | I53: 社名の｢ベターデイズ(Betterdays)｣には ”より良い明日”や”より良い未来”という想いを込めました。 北海道の産地・生産者と連携して ”より良い食文化”をご提案します！
A54: GYB | B54: 五洋物産 | D54: 北海道札幌市白石区菊水元町6条１－１－３０ | E54: 011-595-7288 | F54: 吉野 | G54: 月末締翌月末払い | I54: 長年培ってきた知床前浜の魚貝類ファーストのものづくりは、知床の魚貝マイスターが競りにおける目利き力とスタッフによる加工技術によって成しえるものであります。
A55: STK | B55: 知床工房 | D55: WEBで出てこず
A56: AUT | B56: オーセントホテル小樽
A57: KTR | B57: 京樽
A58: OTS | B58: 小樽水産加工業協同組合
A59: YAS | B59: 湯浅醤油
A60: FJK | B60: 藤岡 睦夫
...

Sheet 商品マスタ
A1: ※灰色セルは自動入力
A2: 大分類 | B2: 小分類 | C2: 仕入先 | D2: 商品連番 | E2: 商品名 | F2: 初出フラグ | G2: シリアル | H2: 単位 | I2: 容量 | J2: 発注ロット | K2: 荷姿 | L2: 仕入 単価 | M2: 仕入価格更新日 | N2: 参考上代 （税込) | O2: 販売先利益率 （上代加味） | P2: 標準国内送料率 | Q2: 標準国内送料 | R2: 実績 国内送料 | S2: 国内送料 | T2: 仕入単価+国内送料 | U2: 海外定価 （20％） | V2: 海外定価 粗利 | W2: 国内定価 （15％） | X2: 国内定価 粗利 | Y2: 税率 | Z2: 賞味期限 | AA2: 温度帯 | AB2: 発注リードタイム | AC2: JANコード | AD2: 商品特徴 | AE2: 画像名 | AF2: EEZO 掲載可否 | AG2: 申し送り事項 在庫、支払い条件、税率、送料条件など
A3: その他 | B3: 調味料 | C3: 北見ハッカ通商 | D3: ="PRD_SNJ_"& _xlfn.XLOOKUP(商品マスタ[[#This Row],[仕入先]],テーブル1[仕入先名],テーブル1[仕入先コード],"XXX",0,1)& "_"& 商品マスタ[[#This Row],[シリアル]]& "_"& TEXT(COUNTIFS(商品マスタ!$C$3:C3,商品マスタ[[#This Row],[仕入先]],商品マスタ!$E$3:E3,商品マスタ[[#This Row],[商品名]]), "00") | E3: ハッカ油スプレー | F3: =IF(COUNTIFS($C$3:C3,商品マスタ[[#This Row],[仕入先]],$E$3:E3,商品マスタ[[#This Row],[商品名]]) = 1, 1,0) | G3: =TEXT(SUMIF($C$3:C3,商品マスタ[[#This Row],[仕入先]],$F$3:F3), "0000") | H3: 本 | I3: 11.5ml | J3: 100 | L3: 715 | M3: 45950 | N3: 1188 | O3: =IF(COUNT(商品マスタ[[#This Row],[参考上代 （税込)]]) > 0, (商品マスタ[[#This Row],[参考上代 （税込)]]-商品マスタ[[#This Row],[国内定価 （15％）]])/(商品マスタ[[#This Row],[参考上代 （税込)]]/1.08), "") | P3: 0.1 | Q3: =商品マスタ[[#This Row],[仕入 単価]]*商品マスタ[[#This Row],[標準国内送料率]] | S3: =IF(ISBLANK(商品マスタ[[#This Row],[実績 国内送料]]),商品マスタ[[#This Row],[標準国内送料]],) | T3: =商品マスタ[[#This Row],[仕入 単価]]+商品マスタ[[#This Row],[国内送料]] | U3: =ROUNDUP(商品マスタ[[#This Row],[仕入単価+国内送料]]/0.8,-1) | V3: =商品マスタ[[#This Row],[海外定価 （20％）]]-商品マスタ[[#This Row],[仕入単価+国内送料]] | W3: =ROUNDUP(商品マスタ[[#This Row],[仕入単価+国内送料]]/0.85,-1) | X3: =商品マスタ[[#This Row],[国内定価 （15％）]]-商品マスタ[[#This Row],[仕入単価+国内送料]] | Y3: 0.08 | Z3: 3年 | AA3: 常温 | AB3: 7日 | AC3: 4985146001639 | AD3: 北のかおり ハッカ油、人気のスプレータイプです。天然ミントの瓶詰です。安心の食品無添加です。 | AF3: 〇 | AG3: 前金。振込後発送。ハッカ油は軽減税率8％対象。販売の際は「定価厳守」契約書交わし済み
A4: その他 | B4: 調味料 | C4: 北見ハッカ通商 | D4: ="PRD_SNJ_"& _xlfn.XLOOKUP(商品マスタ[[#This Row],[仕入先]],テーブル1[仕入先名],テーブル1[仕入先コード],"XXX",0,1)& "_"& 商品マスタ[[#This Row],[シリアル]]& "_"& TEXT(COUNTIFS(商品マスタ!$C$3:C4,商品マスタ[[#This Row],[仕入先]],商品マスタ!$E$3:E4,商品マスタ[[#This Row],[商品名]]), "00") | E4: ハッカ油スプレーR | F4: =IF(COUNTIFS($C$3:C4,商品マスタ[[#This Row],[仕入先]],$E$3:E4,商品マスタ[[#This Row],[商品名]]) = 1, 1,0) | G4: =TEXT(SUMIF($C$3:C4,商品マスタ[[#This Row],[仕入先]],$F$3:F4), "0000") | H4: 本 | I4: 10ml | J4: 100 | L4: 650 | M4: 45950 | N4: 1080 | O4: =IF(COUNT(商品マスタ[[#This Row],[参考上代 （税込)]]) > 0, (商品マスタ[[#This Row],[参考上代 （税込)]]-商品マスタ[[#This Row],[国内定価 （15％）]])/(商品マスタ[[#This Row],[参考上代 （税込)]]/1.08), "") | P4: 0.1 | Q4: =商品マスタ[[#This Row],[仕入 単価]]*商品マスタ[[#This Row],[標準国内送料率]] | S4: =IF(ISBLANK(商品マスタ[[#This Row],[実績 国内送料]]),商品マスタ[[#This Row],[標準国内送料]],) | T4: =商品マスタ[[#This Row],[仕入 単価]]+商品マスタ[[#This Row],[国内送料]] | U4: =ROUNDUP(商品マスタ[[#This Row],[仕入単価+国内送料]]/0.8,-1) | V4: =商品マスタ[[#This Row],[海外定価 （20％）]]-商品マスタ[[#This Row],[仕入単価+国内送料]] | W4: =ROUNDUP(商品マスタ[[#This Row],[仕入単価+国内送料]]/0.85,-1) | X4: =商品マスタ[[#This Row],[国内定価 （15％）]]-商品マスタ[[#This Row],[仕入単価+国内送料]] | Y4: 0.08 | Z4: 3年 | AA4: 常温 | AB4: 7日 | AC4: 4985146001042 | AD4: 少量ずつ塗るのに便利なロールオンタイプ。お好きな場所にクルクルと塗り込んでください。天然ミントで、安心の食品無添加です。 | AF4: 〇 | AG4: 前金。振込後発送。ハッカ油は軽減税率8％対象。販売の際は「定価厳守」契約書交わし済み
A5: 菓子 | B5: 和菓子 | C5: 北見ハッカ通商 | D5: ="PRD_SNJ_"& _xlfn.XLOOKUP(商品マスタ[[#This Row],[仕入先]],テーブル1[仕入先名],テーブル1[仕入先コード],"XXX",0,1)& "_"& 商品マスタ[[#This Row],[シリアル]]& "_"& TEXT(COUNTIFS(商品マスタ!$C$3:C5,商品マスタ[[#This Row],[仕入先]],商品マスタ!$E$3:E5,商品マスタ[[#This Row],[商品名]]), "00") | E5: ハッカ飴 | F5: =IF(COUNTIFS($C$3:C5,商品マスタ[[#This Row],[仕入先]],$E$3:E5,商品マスタ[[#This Row],[商品名]]) = 1, 1,0) | G5: =TEXT(SUMIF($C$3:C5,商品マスタ[[#This Row],[仕入先]],$F$3:F5), "0000") | H5: 袋 | I5: 240g | J5: 200 | L5: 287 | M5: 45950 | N5: 443 | O5: =IF(COUNT(商品マスタ[[#This Row],[参考上代 （税込)]]) > 0, (商品マスタ[[#This Row],[参考上代 （税込)]]-商品マスタ[[#This Row],[国内定価 （15％）]])/(商品マスタ[[#This Row],[参考上代 （税込)]]/1.08), "") | P5: 0.1 | Q5: =商品マスタ[[#This Row],[仕入 単価]]*商品マスタ[[#This Row],[標準国内送料率]] | S5: =IF(ISBLANK(商品マスタ[[#This Row],[実績 国内送料]]),商品マスタ[[#This Row],[標準国内送料]],) | T5: =商品マスタ[[#This Row],[仕入 単価]]+商品マスタ[[#This Row],[国内送料]] | U5: =ROUNDUP(商品マスタ[[#This Row],[仕入単価+国内送料]]/0.8,-1) | V5: =商品マスタ[[#This Row],[海外定価 （20％）]]-商品マスタ[[#This Row],[仕入単価+国内送料]] | W5: =ROUNDUP(商品マスタ[[#This Row],[仕入単価+国内送料]]/0.85,-1) | X5: =商品マスタ[[#This Row],[国内定価 （15％）]]-商品マスタ[[#This Row],[仕入単価+国内送料]] | Y5: 0.08 | Z5: 13か月 | AA5: 常温 | AB5: 7日 | AC5: 4985146000649 | AD5: ロングセラー商品、ハッカ飴です。 | AF5: 〇 | AG5: 前金。振込後発送。販売の際は「定価厳守」契約書交わし済み
A6: 菓子 | B6: 和菓子 | C6: 北見ハッカ通商 | D6: ="PRD_SNJ_"& _xlfn.XLOOKUP(商品マスタ[[#This Row],[仕入先]],テーブル1[仕入先名],テーブル1[仕入先コード],"XXX",0,1)& "_"& 商品マスタ[[#This Row],[シリアル]]& "_"& TEXT(COUNTIFS(商品マスタ!$C$3:C6,商品マスタ[[#This Row],[仕入先]],商品マスタ!$E$3:E6,商品マスタ[[#This Row],[商品名]]), "00") | E6: CHOCOMINT CANDY | F6: =IF(COUNTIFS($C$3:C6,商品マスタ[[#This Row],[仕入先]],$E$3:E6,商品マスタ[[#This Row],[商品名]]) = 1, 1,0) | G6: =TEXT(SUMIF($C$3:C6,商品マスタ[[#This Row],[仕入先]],$F$3:F6), "0000") | H6: 袋 | I6: 170g | J6: 200 | L6: 287 | M6: 45950 | N6: 442 | O6: =IF(COUNT(商品マスタ[[#This Row],[参考上代 （税込)]]) > 0, (商品マスタ[[#This Row],[参考上代 （税込)]]-商品マスタ[[#This Row],[国内定価 （15％）]])/(商品マスタ[[#This Row],[参考上代 （税込)]]/1.08), "") | P6: 0.1 | Q6: =商品マスタ[[#This Row],[仕入 単価]]*商品マスタ[[#This Row],[標準国内送料率]] | S6: =IF(ISBLANK(商品マスタ[[#This Row],[実績 国内送料]]),商品マスタ[[#This Row],[標準国内送料]],) | T6: =商品マスタ[[#This Row],[仕入 単価]]+商品マスタ[[#This Row],[国内送料]] | U6: =ROUNDUP(商品マスタ[[#This Row],[仕入単価+国内送料]]/0.8,-1) | V6: =商品マスタ[[#This Row],[海外定価 （20％）]]-商品マスタ[[#This Row],[仕入単価+国内送料]] | W6: =ROUNDUP(商品マスタ[[#This Row],[仕入単価+国内送料]]/0.85,-1) | X6: =商品マスタ[[#This Row],[国内定価 （15％）]]-商品マスタ[[#This Row],[仕入単価+国内送料]] | Y6: 0.08 | Z6: 13か月 | AA6: 常温 | AB6: 7日 | AC6: 4985146000908 | AD6: 和種ハッカと香ばしいカカオニブが混ざり合う、チョコミント風味のキャンディーです。 | AF6: 〇 | AG6: 前金。振込後発送。販売の際は「定価厳守」契約書交わし済み
A7: 菓子 | B7: 和菓子 | C7: 北見ハッカ通商 | D7: ="PRD_SNJ_"& _xlfn.XLOOKUP(商品マスタ[[#This Row],[仕入先]],テーブル1[仕入先名],テーブル1[仕入先コード],"XXX",0,1)& "_"& 商品マスタ[[#This Row],[シリアル]]& "_"& TEXT(COUNTIFS(商品マスタ!$C$3:C7,商品マスタ[[#This Row],[仕入先]],商品マスタ!$E$3:E7,商品マスタ[[#This Row],[商品名]]), "00") | E7: フルーツミントキャンデー・パイナップル味 | F7: =IF(COUNTIFS($C$3:C7,商品マスタ[[#This Row],[仕入先]],$E$3:E7,商品マスタ[[#This Row],[商品名]]) = 1, 1,0) | G7: =TEXT(SUMIF($C$3:C7,商品マスタ[[#This Row],[仕入先]],$F$3:F7), "0000") | H7: 袋 | I7: 170g | J7: 24 | K7: 24袋/箱 | L7: 287 | M7: 45950 | N7: 442 | O7: =IF(COUNT(商品マスタ[[#This Row],[参考上代 （税込)]]) > 0, (商品マスタ[[#This Row],[参考上代 （税込)]]-商品マスタ[[#This Row],[国内定価 （15％）]])/(商品マスタ[[#This Row],[参考上代 （税込)]]/1.08), "") | P7: 0.1 | Q7: =商品マスタ[[#This Row],[仕入 単価]]*商品マスタ[[#This Row],[標準国内送料率]] | S7: =IF(ISBLANK(商品マスタ[[#This Row],[実績 国内送料]]),商品マスタ[[#This Row],[標準国内送料]],) | T7: =商品マスタ[[#This Row],[仕入 単価]]+商品マスタ[[#This Row],[国内送料]] | U7: =ROUNDUP(商品マスタ[[#This Row],[仕入単価+国内送料]]/0.8,-1) | V7: =商品マスタ[[#This Row],[海外定価 （20％）]]-商品マスタ[[#This Row],[仕入単価+国内送料]] | W7: =ROUNDUP(商品マスタ[[#This Row],[仕入単価+国内送料]]/0.85,-1) | X7: =商品マスタ[[#This Row],[国内定価 （15％）]]-商品マスタ[[#This Row],[仕入単価+国内送料]] | Y7: 0.08 | Z7: 13か月 | AA7: 常温 | AB7: 7日 | AC7: 4985146000953 | AD7: ミントの仲間「パイナップルミント」をイメージしたキャンディー。 南国を想わせる甘く芳醇なパイナップルの風味とミントの清涼感をミックスして、爽やかな甘さのある味に仕上げました。 | AF7: 〇 | AG7: 前金。振込後発送。販売の際は「定価厳守」契約書交わし済み
A8: 菓子 | B8: 和菓子 | C8: 北見ハッカ通商 | D8: ="PRD_SNJ_"& _xlfn.XLOOKUP(商品マスタ[[#This Row],[仕入先]],テーブル1[仕入先名],テーブル1[仕入先コード],"XXX",0,1)& "_"& 商品マスタ[[#This Row],[シリアル]]& "_"& TEXT(COUNTIFS(商品マスタ!$C$3:C8,商品マスタ[[#This Row],[仕入先]],商品マスタ!$E$3:E8,商品マスタ[[#This Row],[商品名]]), "00") | E8: フルーツミントキャンデー・アップル味 | F8: =IF(COUNTIFS($C$3:C8,商品マスタ[[#This Row],[仕入先]],$E$3:E8,商品マスタ[[#This Row],[商品名]]) = 1, 1,0) | G8: =TEXT(SUMIF($C$3:C8,商品マスタ[[#This Row],[仕入先]],$F$3:F8), "0000") | H8: 袋 | I8: 170g | J8: 24 | K8: 24袋/箱 | L8: 287 | M8: 45950 | N8: 442 | O8: =IF(COUNT(商品マスタ[[#This Row],[参考上代 （税込)]]) > 0, (商品マスタ[[#This Row],[参考上代 （税込)]]-商品マスタ[[#This Row],[国内定価 （15％）]])/(商品マスタ[[#This Row],[参考上代 （税込)]]/1.08), "") | P8: 0.1 | Q8: =商品マスタ[[#This Row],[仕入 単価]]*商品マスタ[[#This Row],[標準国内送料率]] | S8: =IF(ISBLANK(商品マスタ[[#This Row],[実績 国内送料]]),商品マスタ[[#This Row],[標準国内送料]],) | T8: =商品マスタ[[#This Row],[仕入 単価]]+商品マスタ[[#This Row],[国内送料]] | U8: =ROUNDUP(商品マスタ[[#This Row],[仕入単価+国内送料]]/0.8,-1) | V8: =商品マスタ[[#This Row],[海外定価 （20％）]]-商品マスタ[[#This Row],[仕入単価+国内送料]] | W8: =ROUNDUP(商品マスタ[[#This Row],[仕入単価+国内送料]]/0.85,-1) | X8: =商品マスタ[[#This Row],[国内定価 （15％）]]-商品マスタ[[#This Row],[仕入単価+国内送料]] | Y8: 0.08 | Z8: 13か月 | AA8: 常温 | AB8: 7日 | AC8: 4985146000960 | AD8: ミントの仲間「アップルミント」をイメージしたミントキャンディー。アップルの後味さっぱりとした甘さとミントの清涼感を合わせて、軽やかなスッキリとした味に仕上げました。 | AF8: 〇 | AG8: 前金。振込後発送。販売の際は「定価厳守」契約書交わし済み
A9: 菓子 | B9: 和菓子 | C9: 北見ハッカ通商 | D9: ="PRD_SNJ_"& _xlfn.XLOOKUP(商品マスタ[[#This Row],[仕入先]],テーブル1[仕入先名],テーブル1[仕入先コード],"XXX",0,1)& "_"& 商品マスタ[[#This Row],[シリアル]]& "_"& TEXT(COUNTIFS(商品マスタ!$C$3:C9,商品マスタ[[#This Row],[仕入先]],商品マスタ!$E$3:E9,商品マスタ[[#This Row],[商品名]]), "00") | E9: フルーツミントキャンデー・レモン味 | F9: =IF(COUNTIFS($C$3:C9,商品マスタ[[#This Row],[仕入先]],$E$3:E9,商品マスタ[[#This Row],[商品名]]) = 1, 1,0) | G9: =TEXT(SUMIF($C$3:C9,商品マスタ[[#This Row],[仕入先]],$F$3:F9), "0000") | H9: 袋 | I9: 170g | J9: 24 | K9: 24袋/箱 | L9: 287 | M9: 45950 | N9: 442 | O9: =IF(COUNT(商品マスタ[[#This Row],[参考上代 （税込)]]) > 0, (商品マスタ[[#This Row],[参考上代 （税込)]]-商品マスタ[[#This Row],[国内定価 （15％）]])/(商品マスタ[[#This Row],[参考上代 （税込)]]/1.08), "") | P9: 0.1 | Q9: =商品マスタ[[#This Row],[仕入 単価]]*商品マスタ[[#This Row],[標準国内送料率]] | S9: =IF(ISBLANK(商品マスタ[[#This Row],[実績 国内送料]]),商品マスタ[[#This Row],[標準国内送料]],) | T9: =商品マスタ[[#This Row],[仕入 単価]]+商品マスタ[[#This Row],[国内送料]] | U9: =ROUNDUP(商品マスタ[[#This Row],[仕入単価+国内送料]]/0.8,-1) | V9: =商品マスタ[[#This Row],[海外定価 （20％）]]-商品マスタ[[#This Row],[仕入単価+国内送料]] | W9: =ROUNDUP(商品マスタ[[#This Row],[仕入単価+国内送料]]/0.85,-1) | X9: =商品マスタ[[#This Row],[国内定価 （15％）]]-商品マスタ[[#This Row],[仕入単価+国内送料]] | Y9: 0.08 | Z9: 13か月 | AA9: 常温 | AB9: 7日 | AC9: 4985146000922 | AD9: ミントの仲間「レモンバーム、レモンミント」をイメージしたキャンディー。レモンのしっかりとした酸味とミントの清涼感をミックスして、爽やかなキレのある味に仕上げました。 | AF9: 〇 | AG9: 前金。振込後発送。販売の際は「定価厳守」契約書交わし済み
A10: 菓子 | B10: 和菓子 | C10: 北見ハッカ通商 | D10: ="PRD_SNJ_"& _xlfn.XLOOKUP(商品マスタ[[#This Row],[仕入先]],テーブル1[仕入先名],テーブル1[仕入先コード],"XXX",0,1)& "_"& 商品マスタ[[#This Row],[シリアル]]& "_"& TEXT(COUNTIFS(商品マスタ!$C$3:C10,商品マスタ[[#This Row],[仕入先]],商品マスタ!$E$3:E10,商品マスタ[[#This Row],[商品名]]), "00") | E10: フルーツミントキャンデー・オレンジ味 | F10: =IF(COUNTIFS($C$3:C10,商品マスタ[[#This Row],[仕入先]],$E$3:E10,商品マスタ[[#This Row],[商品名]]) = 1, 1,0) | G10: =TEXT(SUMIF($C$3:C10,商品マスタ[[#This Row],[仕入先]],$F$3:F10), "0000") | H10: 袋 | I10: 170g | J10: 24 | K10: 24袋/箱 | L10: 287 | M10: 45950 | N10: 442 | O10: =IF(COUNT(商品マスタ[[#This Row],[参考上代 （税込)]]) > 0, (商品マスタ[[#This Row],[参考上代 （税込)]]-商品マスタ[[#This Row],[国内定価 （15％）]])/(商品マスタ[[#This Row],[参考上代 （税込)]]/1.08), "") | P10: 0.1 | Q10: =商品マスタ[[#This Row],[仕入 単価]]*商品マスタ[[#This Row],[標準国内送料率]] | S10: =IF(ISBLANK(商品マスタ[[#This Row],[実績 国内送料]]),商品マスタ[[#This Row],[標準国内送料]],) | T10: =商品マスタ[[#This Row],[仕入 単価]]+商品マスタ[[#This Row],[国内送料]] | U10: =ROUNDUP(商品マスタ[[#This Row],[仕入単価+国内送料]]/0.8,-1) | V10: =商品マスタ[[#This Row],[海外定価 （20％）]]-商品マスタ[[#This Row],[仕入単価+国内送料]] | W10: =ROUNDUP(商品マスタ[[#This Row],[仕入単価+国内送料]]/0.85,-1) | X10: =商品マスタ[[#This Row],[国内定価 （15％）]]-商品マスタ[[#This Row],[仕入単価+国内送料]] | Y10: 0.08 | Z10: 13か月 | AA10: 常温 | AB10: 7日 | AC10: 4985146000946 | AD10: ミントの仲間「オレンジミント」をイメージしたキャンディー。 濃厚なオレンジの風味とミントを合わせて、ジューシーな甘さと香りの広がる味に仕上げました。 | AF10: 〇 | AG10: 前金。振込後発送。販売の際は「定価厳守」契約書交わし済み
A11: 菓子 | B11: 和菓子 | C11: 北見ハッカ通商 | D11: ="PRD_SNJ_"& _xlfn.XLOOKUP(商品マスタ[[#This Row],[仕入先]],テーブル1[仕入先名],テーブル1[仕入先コード],"XXX",0,1)& "_"& 商品マスタ[[#This Row],[シリアル]]& "_"& TEXT(COUNTIFS(商品マスタ!$C$3:C11,商品マスタ[[#This Row],[仕入先]],商品マスタ!$E$3:E11,商品マスタ[[#This Row],[商品名]]), "00") | E11: フルーツミントキャンデー・グレープフルーツ味 | F11: =IF(COUNTIFS($C$3:C11,商品マスタ[[#This Row],[仕入先]],$E$3:E11,商品マスタ[[#This Row],[商品名]]) = 1, 1,0) | G11: =TEXT(SUMIF($C$3:C11,商品マスタ[[#This Row],[仕入先]],$F$3:F11), "0000") | H11: 袋 | I11: 170g | J11: 24 | K11: 24袋/箱 | L11: 287 | M11: 45950 | N11: 442 | O11: =IF(COUNT(商品マスタ[[#This Row],[参考上代 （税込)]]) > 0, (商品マスタ[[#This Row],[参考上代 （税込)]]-商品マスタ[[#This Row],[国内定価 （15％）]])/(商品マスタ[[#This Row],[参考上代 （税込)]]/1.08), "") | P11: 0.1 | Q11: =商品マスタ[[#This Row],[仕入 単価]]*商品マスタ[[#This Row],[標準国内送料率]] | S11: =IF(ISBLANK(商品マスタ[[#This Row],[実績 国内送料]]),商品マスタ[[#This Row],[標準国内送料]],) | T11: =商品マスタ[[#This Row],[仕入 単価]]+商品マスタ[[#This Row],[国内送料]] | U11: =ROUNDUP(商品マスタ[[#This Row],[仕入単価+国内送料]]/0.8,-1) | V11: =商品マスタ[[#This Row],[海外定価 （20％）]]-商品マスタ[[#This Row],[仕入単価+国内送料]] | W11: =ROUNDUP(商品マスタ[[#This Row],[仕入単価+国内送料]]/0.85,-1) | X11: =商品マスタ[[#This Row],[国内定価 （15％）]]-商品マスタ[[#This Row],[仕入単価+国内送料]] | Y11: 0.08 | Z11: 13か月 | AA11: 常温 | AB11: 7日 | AC11: 4985146000984 | AD11: ミントの仲間「グレープフルーツミント」をイメージしたキャンディー。グレープフルーツが持つ柑橘系のさっぱりとした爽やかさにミントの清涼感をミックス。後味スッキリ爽快な味に仕上げました。 | AF11: 〇 | AG11: 前金。振込後発送。販売の際は「定価厳守」契約書交わし済み
A12: 菓子 | B12: 和菓子 | C12: 北見ハッカ通商 | D12: ="PRD_SNJ_"& _xlfn.XLOOKUP(商品マスタ[[#This Row],[仕入先]],テーブル1[仕入先名],テーブル1[仕入先コード],"XXX",0,1)& "_"& 商品マスタ[[#This Row],[シリアル]]& "_"& TEXT(COUNTIFS(商品マスタ!$C$3:C12,商品マスタ[[#This Row],[仕入先]],商品マスタ!$E$3:E12,商品マスタ[[#This Row],[商品名]]), "00") | E12: フルーツミントキャンデー・グレープ味 | F12: =IF(COUNTIFS($C$3:C12,商品マスタ[[#This Row],[仕入先]],$E$3:E12,商品マスタ[[#This Row],[商品名]]) = 1, 1,0) | G12: =TEXT(SUMIF($C$3:C12,商品マスタ[[#This Row],[仕入先]],$F$3:F12), "0000") | H12: 袋 | I12: 180g | J12: 24 | K12: 24袋/箱 | L12: 287 | M12: 45950 | N12: 442 | O12: =IF(COUNT(商品マスタ[[#This Row],[参考上代 （税込)]]) > 0, (商品マスタ[[#This Row],[参考上代 （税込)]]-商品マスタ[[#This Row],[国内定価 （15％）]])/(商品マスタ[[#This Row],[参考上代 （税込)]]/1.08), "") | P12: 0.1 | Q12: =商品マスタ[[#This Row],[仕入 単価]]*商品マスタ[[#This Row],[標準国内送料率]] | S12: =IF(ISBLANK(商品マスタ[[#This Row],[実績 国内送料]]),商品マスタ[[#This Row],[標準国内送料]],) | T12: =商品マスタ[[#This Row],[仕入 単価]]+商品マスタ[[#This Row],[国内送料]] | U12: =ROUNDUP(商品マスタ[[#This Row],[仕入単価+国内送料]]/0.8,-1) | V12: =商品マスタ[[#This Row],[海外定価 （20％）]]-商品マスタ[[#This Row],[仕入単価+国内送料]] | W12: =ROUNDUP(商品マスタ[[#This Row],[仕入単価+国内送料]]/0.85,-1) | X12: =商品マスタ[[#This Row],[国内定価 （15％）]]-商品マスタ[[#This Row],[仕入単価+国内送料]] | Y12: 0.08 | Z12: 13か月 | AA12: 常温 | AB12: 7日 | AC12: 4985146000939 | AD12: グレープのジューシーな甘さと香りにミントの清涼感を合わせて、フルーティーな香り広がる爽やかな味に仕上げました。 | AF12: 〇 | AG12: 前金。振込後発送。販売の際は「定価厳守」契約書交わし済み。税抜仕入額6万以上で無料
A13: 菓子 | B13: 和菓子 | C13: 北見ハッカ通商 | D13: ="PRD_SNJ_"& _xlfn.XLOOKUP(商品マスタ[[#This Row],[仕入先]],テーブル1[仕入先名],テーブル1[仕入先コード],"XXX",0,1)& "_"& 商品マスタ[[#This Row],[シリアル]]& "_"& TEXT(COUNTIFS(商品マスタ!$C$3:C13,商品マスタ[[#This Row],[仕入先]],商品マスタ!$E$3:E13,商品マスタ[[#This Row],[商品名]]), "00") | E13: フルーツミントキャンデー・ピーチ味 | F13: =IF(COUNTIFS($C$3:C13,商品マスタ[[#This Row],[仕入先]],$E$3:E13,商品マスタ[[#This Row],[商品名]]) = 1, 1,0) | G13: =TEXT(SUMIF($C$3:C13,商品マスタ[[#This Row],[仕入先]],$F$3:F13), "0000") | H13: 袋 | I13: 180g | J13: 24 | K13: 24袋/箱 | L13: 287 | M13: 45950 | N13: 442 | O13: =IF(COUNT(商品マスタ[[#This Row],[参考上代 （税込)]]) > 0, (商品マスタ[[#This Row],[参考上代 （税込)]]-商品マスタ[[#This Row],[国内定価 （15％）]])/(商品マスタ[[#This Row],[参考上代 （税込)]]/1.08), "") | P13: 0.1 | Q13: =商品マスタ[[#This Row],[仕入 単価]]*商品マスタ[[#This Row],[標準国内送料率]] | S13: =IF(ISBLANK(商品マスタ[[#This Row],[実績 国内送料]]),商品マスタ[[#This Row],[標準国内送料]],) | T13: =商品マスタ[[#This Row],[仕入 単価]]+商品マスタ[[#This Row],[国内送料]] | U13: =ROUNDUP(商品マスタ[[#This Row],[仕入単価+国内送料]]/0.8,-1) | V13: =商品マスタ[[#This Row],[海外定価 （20％）]]-商品マスタ[[#This Row],[仕入単価+国内送料]] | W13: =ROUNDUP(商品マスタ[[#This Row],[仕入単価+国内送料]]/0.85,-1) | X13: =商品マスタ[[#This Row],[国内定価 （15％）]]-商品マスタ[[#This Row],[仕入単価+国内送料]] | Y13: 0.08 | Z13: 13か月 | AA13: 常温 | AB13: 7日 | AC13: 4985146000977 | AD13: 口の中でジューシーに広がる甘い豊かなピーチの風味とミントの清涼感をマッチさせ、やさしく甘いスッキリした味に仕上げました。 | AF13: 〇 | AG13: 前金。振込後発送。販売の際は「定価厳守」契約書交わし済み。税抜仕入額6万以上で無料
A14: 菓子 | B14: 和菓子 | C14: 北見ハッカ通商 | D14: ="PRD_SNJ_"& _xlfn.XLOOKUP(商品マスタ[[#This Row],[仕入先]],テーブル1[仕入先名],テーブル1[仕入先コード],"XXX",0,1)& "_"& 商品マスタ[[#This Row],[シリアル]]& "_"& TEXT(COUNTIFS(商品マスタ!$C$3:C14,商品マスタ[[#This Row],[仕入先]],商品マスタ!$E$3:E14,商品マスタ[[#This Row],[商品名]]), "00") | E14: フルーツミントキャンデー・ストロベリー味 | F14: =IF(COUNTIFS($C$3:C14,商品マスタ[[#This Row],[仕入先]],$E$3:E14,商品マスタ[[#This Row],[商品名]]) = 1, 1,0) | G14: =TEXT(SUMIF($C$3:C14,商品マスタ[[#This Row],[仕入先]],$F$3:F14), "0000") | H14: 袋 | I14: 180g | J14: 24 | K14: 24袋/箱 | L14: 287 | M14: 45950 | N14: 442 | O14: =IF(COUNT(商品マスタ[[#This Row],[参考上代 （税込)]]) > 0, (商品マスタ[[#This Row],[参考上代 （税込)]]-商品マスタ[[#This Row],[国内定価 （15％）]])/(商品マスタ[[#This Row],[参考上代 （税込)]]/1.08), "") | P14: 0.1 | Q14: =商品マスタ[[#This Row],[仕入 単価]]*商品マスタ[[#This Row],[標準国内送料率]] | S14: =IF(ISBLANK(商品マスタ[[#This Row],[実績 国内送料]]),商品マスタ[[#This Row],[標準国内送料]],) | T14: =商品マスタ[[#This Row],[仕入 単価]]+商品マスタ[[#This Row],[国内送料]] | U14: =ROUNDUP(商品マスタ[[#This Row],[仕入単価+国内送料]]/0.8,-1) | V14: =商品マスタ[[#This Row],[海外定価 （20％）]]-商品マスタ[[#This Row],[仕入単価+国内送料]] | W14: =ROUNDUP(商品マスタ[[#This Row],[仕入単価+国内送料]]/0.85,-1) | X14: =商品マスタ[[#This Row],[国内定価 （15％）]]-商品マスタ[[#This Row],[仕入単価+国内送料]] | Y14: 0.08 | Z14: 13か月 | AA14: 常温 | AB14: 7日 | AC14: 4985146000915 | AD14: ミントの仲間「ストロベリーミント」をイメージしたミントキャンディー。ストロベリーのしっかりとした甘い香りの風味とミントの清涼感を合わせて、フルーティーな甘さとスッキリとした爽やかな味に仕上げました。 | AF14: 〇 | AG14: 前金。振込後発送。販売の際は「定価厳守」契約書交わし済み。税抜仕入額6万以上で無料
A15: 菓子 | B15: 和菓子 | C15: 北見ハッカ通商 | D15: ="PRD_SNJ_"& _xlfn.XLOOKUP(商品マスタ[[#This Row],[仕入先]],テーブル1[仕入先名],テーブル1[仕入先コード],"XXX",0,1)& "_"& 商品マスタ[[#This Row],[シリアル]]& "_"& TEXT(COUNTIFS(商品マスタ!$C$3:C15,商品マスタ[[#This Row],[仕入先]],商品マスタ!$E$3:E15,商品マスタ[[#This Row],[商品名]]), "00") | E15: フルーツミント Mixキャンディ BOX | F15: =IF(COUNTIFS($C$3:C15,商品マスタ[[#This Row],[仕入先]],$E$3:E15,商品マスタ[[#This Row],[商品名]]) = 1, 1,0) | G15: =TEXT(SUMIF($C$3:C15,商品マスタ[[#This Row],[仕入先]],$F$3:F15), "0000") | H15: 缶 | I15: 360g | J15: 30 | K15: 30缶/箱 | L15: 700 | M15: 45950 | N15: 1080 | O15: =IF(COUNT(商品マスタ[[#This Row],[参考上代 （税込)]]) > 0, (商品マスタ[[#This Row],[参考上代 （税込)]]-商品マスタ[[#This Row],[国内定価 （15％）]])/(商品マスタ[[#This Row],[参考上代 （税込)]]/1.08), "") | P15: 0.1 | Q15: =商品マスタ[[#This Row],[仕入 単価]]*商品マスタ[[#This Row],[標準国内送料率]] | S15: =IF(ISBLANK(商品マスタ[[#This Row],[実績 国内送料]]),商品マスタ[[#This Row],[標準国内送料]],) | T15: =商品マスタ[[#This Row],[仕入 単価]]+商品マスタ[[#This Row],[国内送料]] | U15: =ROUNDUP(商品マスタ[[#This Row],[仕入単価+国内送料]]/0.8,-1) | V15: =商品マスタ[[#This Row],[海外定価 （20％）]]-商品マスタ[[#This Row],[仕入単価+国内送料]] | W15: =ROUNDUP(商品マスタ[[#This Row],[仕入単価+国内送料]]/0.85,-1) | X15: =商品マスタ[[#This Row],[国内定価 （15％）]]-商品マスタ[[#This Row],[仕入単価+国内送料]] | Y15: 0.08 | Z15: 13か月 | AA15: 常温 | AB15: 3週間 | AC15: 4985146001134 | AD15: ※受注生産品 ロングセラーのハッカ飴に、カカオニブを使用したチョコミントキャンディー、8種類のフルーツミントキャンディーを詰め合わせた、10種類の味をお楽しみいただけるキャンディーBOXです。 | AF15: 〇 | AG15: 前金。振込後発送。販売の際は「定価厳守」契約書交わし済み。税抜仕入額6万以上で無料
A16: 菓子 | B16: 和菓子 | C16: 北見ハッカ通商 | D16: ="PRD_SNJ_"& _xlfn.XLOOKUP(商品マスタ[[#This Row],[仕入先]],テーブル1[仕入先名],テーブル1[仕入先コード],"XXX",0,1)& "_"& 商品マスタ[[#This Row],[シリアル]]& "_"& TEXT(COUNTIFS(商品マスタ!$C$3:C16,商品マスタ[[#This Row],[仕入先]],商品マスタ!$E$3:E16,商品マスタ[[#This Row],[商品名]]), "00") | E16: ハッカ飴（メントール増量）缶 | F16: =IF(COUNTIFS($C$3:C16,商品マスタ[[#This Row],[仕入先]],$E$3:E16,商品マスタ[[#This Row],[商品名]]) = 1, 1,0) | G16: =TEXT(SUMIF($C$3:C16,商品マスタ[[#This Row],[仕入先]],$F$3:F16), "0000") | H16: 缶 | I16: 170g | J16: 100 | K16: 100缶/箱 | L16: 385 | M16: 45950 | N16: 594 | O16: =IF(COUNT(商品マスタ[[#This Row],[参考上代 （税込)]]) > 0, (商品マスタ[[#This Row],[参考上代 （税込)]]-商品マスタ[[#This Row],[国内定価 （15％）]])/(商品マスタ[[#This Row],[参考上代 （税込)]]/1.08), "") | P16: 0.1 | Q16: =商品マスタ[[#This Row],[仕入 単価]]*商品マスタ[[#This Row],[標準国内送料率]] | S16: =IF(ISBLANK(商品マスタ[[#This Row],[実績 国内送料]]),商品マスタ[[#This Row],[標準国内送料]],) | T16: =商品マスタ[[#This Row],[仕入 単価]]+商品マスタ[[#This Row],[国内送料]] | U16: =ROUNDUP(商品マスタ[[#This Row],[仕入単価+国内送料]]/0.8,-1) | V16: =商品マスタ[[#This Row],[海外定価 （20％）]]-商品マスタ[[#This Row],[仕入単価+国内送料]] | W16: =ROUNDUP(商品マスタ[[#This Row],[仕入単価+国内送料]]/0.85,-1) | X16: =商品マスタ[[#This Row],[国内定価 （15％）]]-商品マスタ[[#This Row],[仕入単価+国内送料]] | Y16: 0.08 | Z16: 13か月 | AA16: 常温 | AB16: 3週間 | AC16: 4985146000243 | AD16: ※受注生産品 メントール1.5倍増量、スッキリ感が強めのハッカ飴です。 | AF16: 〇 | AG16: 前金。振込後発送。販売の際は「定価厳守」契約書交わし済み。税抜仕入額6万以上で無料
A17: その他 | B17: 調味料 | C17: 北見ハッカ通商 | D17: ="PRD_SNJ_"& _xlfn.XLOOKUP(商品マスタ[[#This Row],[仕入先]],テーブル1[仕入先名],テーブル1[仕入先コード],"XXX",0,1)& "_"& 商品マスタ[[#This Row],[シリアル]]& "_"& TEXT(COUNTIFS(商品マスタ!$C$3:C17,商品マスタ[[#This Row],[仕入先]],商品マスタ!$E$3:E17,商品マスタ[[#This Row],[商品名]]), "00") | E17: Mentab（メンタブ） | F17: =IF(COUNTIFS($C$3:C17,商品マスタ[[#This Row],[仕入先]],$E$3:E17,商品マスタ[[#This Row],[商品名]]) = 1, 1,0) | G17: =TEXT(SUMIF($C$3:C17,商品マスタ[[#This Row],[仕入先]],$F$3:F17), "0000") | H17: 個 | I17: 9g（70粒) | J17: 144 | K17: 144個/箱 | L17: 175 | M17: 45950 | N17: 270 | O17: =IF(COUNT(商品マスタ[[#This Row],[参考上代 （税込)]]) > 0, (商品マスタ[[#This Row],[参考上代 （税込)]]-商品マスタ[[#This Row],[国内定価 （15％）]])/(商品マスタ[[#This Row],[参考上代 （税込)]]/1.08), "") | P17: 0.1 | Q17: =商品マスタ[[#This Row],[仕入 単価]]*商品マスタ[[#This Row],[標準国内送料率]] | S17: =IF(ISBLANK(商品マスタ[[#This Row],[実績 国内送料]]),商品マスタ[[#This Row],[標準国内送料]],) | T17: =商品マスタ[[#This Row],[仕入 単価]]+商品マスタ[[#This Row],[国内送料]] | U17: =ROUNDUP(商品マスタ[[#This Row],[仕入単価+国内送料]]/0.8,-1) | V17: =商品マスタ[[#This Row],[海外定価 （20％）]]-商品マスタ[[#This Row],[仕入単価+国内送料]] | W17: =ROUNDUP(商品マスタ[[#This Row],[仕入単価+国内送料]]/0.85,-1) | X17: =商品マスタ[[#This Row],[国内定価 （15％）]]-商品マスタ[[#This Row],[仕入単価+国内送料]] | Y17: 0.08 | Z17: 1年 | AA17: 常温 | AB17: 3週間 | AC17: 4985146000458 | AD17: ※受注生産品 「北海道産和種ハッカ」配合のタブレット菓子です。 | AF17: 〇 | AG17: 前金。振込後発送。販売の際は「定価厳守」契約書交わし済み。税抜仕入額6万以上で無料
A18: 菓子 | B18: 洋菓子 | C18: 北見ハッカ通商 | D18: ="PRD_SNJ_"& _xlfn.XLOOKUP(商品マスタ[[#This Row],[仕入先]],テーブル1[仕入先名],テーブル1[仕入先コード],"XXX",0,1)& "_"& 商品マスタ[[#This Row],[シリアル]]& "_"& TEXT(COUNTIFS(商品マスタ!$C$3:C18,商品マスタ[[#This Row],[仕入先]],商品マスタ!$E$3:E18,商品マスタ[[#This Row],[商品名]]), "00") | E18: Mentab（メンタブ）チョコミント味 | F18: =IF(COUNTIFS($C$3:C18,商品マスタ[[#This Row],[仕入先]],$E$3:E18,商品マスタ[[#This Row],[商品名]]) = 1, 1,0) | G18: =TEXT(SUMIF($C$3:C18,商品マスタ[[#This Row],[仕入先]],$F$3:F18), "0000") | H18: 個 | I18: 9g（70粒） | J18: 144 | K18: 144個/箱 | L18: 175 | M18: 45950 | N18: 270 | O18: =IF(COUNT(商品マスタ[[#This Row],[参考上代 （税込)]]) > 0, (商品マスタ[[#This Row],[参考上代 （税込)]]-商品マスタ[[#This Row],[国内定価 （15％）]])/(商品マスタ[[#This Row],[参考上代 （税込)]]/1.08), "") | P18: 0.1 | Q18: =商品マスタ[[#This Row],[仕入 単価]]*商品マスタ[[#This Row],[標準国内送料率]] | S18: =IF(ISBLANK(商品マスタ[[#This Row],[実績 国内送料]]),商品マスタ[[#This Row],[標準国内送料]],) | T18: =商品マスタ[[#This Row],[仕入 単価]]+商品マスタ[[#This Row],[国内送料]] | U18: =ROUNDUP(商品マスタ[[#This Row],[仕入単価+国内送料]]/0.8,-1) | V18: =商品マスタ[[#This Row],[海外定価 （20％）]]-商品マスタ[[#This Row],[仕入単価+国内送料]] | W18: =ROUNDUP(商品マスタ[[#This Row],[仕入単価+国内送料]]/0.85,-1) | X18: =商品マスタ[[#This Row],[国内定価 （15％）]]-商品マスタ[[#This Row],[仕入単価+国内送料]] | Y18: 0.08 | Z18: 1年 | AA18: 常温 | AB18: 3週間 | AC18: 4985146000830 | AD18: ※受注生産品 やさしいチョコの風味と爽やかなミントの清涼感が新しいタブレットです。 | AF18: 〇 | AG18: 前金。振込後発送。販売の際は「定価厳守」契約書交わし済み。税抜仕入額6万以上で無料
A19: 菓子 | B19: 洋菓子 | C19: CHISE GARDEN | D19: ="PRD_SNJ_"& _xlfn.XLOOKUP(商品マスタ[[#This Row],[仕入先]],テーブル1[仕入先名],テーブル1[仕入先コード],"XXX",0,1)& "_"& 商品マスタ[[#This Row],[シリアル]]& "_"& TEXT(COUNTIFS(商品マスタ!$C$3:C19,商品マスタ[[#This Row],[仕入先]],商品マスタ!$E$3:E19,商品マスタ[[#This Row],[商品名]]), "00") | E19: 野草番茶 | F19: =IF(COUNTIFS($C$3:C19,商品マスタ[[#This Row],[仕入先]],$E$3:E19,商品マスタ[[#This Row],[商品名]]) = 1, 1,0) | G19: =TEXT(SUMIF($C$3:C19,商品マスタ[[#This Row],[仕入先]],$F$3:F19), "0000") | H19: 袋 | I19: 50g | J19: 50 | L19: 560 | M19: 45951 | N19: 864 | O19: =IF(COUNT(商品マスタ[[#This Row],[参考上代 （税込)]]) > 0, (商品マスタ[[#This Row],[参考上代 （税込)]]-商品マスタ[[#This Row],[国内定価 （15％）]])/(商品マスタ[[#This Row],[参考上代 （税込)]]/1.08), "") | P19: 0.1 | Q19: =商品マスタ[[#This Row],[仕入 単価]]*商品マスタ[[#This Row],[標準国内送料率]] | R19: 1000 | S19: =IF(ISBLANK(商品マスタ[[#This Row],[実績 国内送料]]),商品マスタ[[#This Row],[標準国内送料]],) | T19: =商品マスタ[[#This Row],[仕入 単価]]+商品マスタ[[#This Row],[国内送料]] | U19: =ROUNDUP(商品マスタ[[#This Row],[仕入単価+国内送料]]/0.8,-1) | V19: =商品マスタ[[#This Row],[海外定価 （20％）]]-商品マスタ[[#This Row],[仕入単価+国内送料]] | W19: =ROUNDUP(商品マスタ[[#This Row],[仕入単価+国内送料]]/0.85,-1) | X19: =商品マスタ[[#This Row],[国内定価 （15％）]]-商品マスタ[[#This Row],[仕入単価+国内送料]] | Y19: 0.08 | Z19: 1年 | AA19: 常温 | AB19: 7日 | AC19: 4595430036010 | AD19: 地元の有名ホテルのウェルカムドリンクとしても人気の野草番茶。 材料のほとんどがニセコ町産で、ガーデンで採れたハーブもブレンドしています。 | AF19: 〇 | AG19: ロット50袋割れ送料実費、混載50袋可
A20: 菓子 | B20: 洋菓子 | C20: CHISE GARDEN | D20: ="PRD_SNJ_"& _xlfn.XLOOKUP(商品マスタ[[#This Row],[仕入先]],テーブル1[仕入先名],テーブル1[仕入先コード],"XXX",0,1)& "_"& 商品マスタ[[#This Row],[シリアル]]& "_"& TEXT(COUNTIFS(商品マスタ!$C$3:C20,商品マスタ[[#This Row],[仕入先]],商品マスタ!$E$3:E20,商品マスタ[[#This Row],[商品名]]), "00") | E20: ハーブティ | F20: =IF(COUNTIFS($C$3:C20,商品マスタ[[#This Row],[仕入先]],$E$3:E20,商品マスタ[[#This Row],[商品名]]) = 1, 1,0) | G20: =TEXT(SUMIF($C$3:C20,商品マスタ[[#This Row],[仕入先]],$F$3:F20), "0000") | H20: 袋 | I20: 20g | J20: 50 | L20: 560 | M20: 45951 | N20: 864 | O20: =IF(COUNT(商品マスタ[[#This Row],[参考上代 （税込)]]) > 0, (商品マスタ[[#This Row],[参考上代 （税込)]]-商品マスタ[[#This Row],[国内定価 （15％）]])/(商品マスタ[[#This Row],[参考上代 （税込)]]/1.08), "") | P20: 0.1 | Q20: =商品マスタ[[#This Row],[仕入 単価]]*商品マスタ[[#This Row],[標準国内送料率]] | R20: 1000 | S20: =IF(ISBLANK(商品マスタ[[#This Row],[実績 国内送料]]),商品マスタ[[#This Row],[標準国内送料]],) | T20: =商品マスタ[[#This Row],[仕入 単価]]+商品マスタ[[#This Row],[国内送料]] | U20: =ROUNDUP(商品マスタ[[#This Row],[仕入単価+国内送料]]/0.8,-1) | V20: =商品マスタ[[#This Row],[海外定価 （20％）]]-商品マスタ[[#This Row],[仕入単価+国内送料]] | W20: =ROUNDUP(商品マスタ[[#This Row],[仕入単価+国内送料]]/0.85,-1) | X20: =商品マスタ[[#This Row],[国内定価 （15％）]]-商品マスタ[[#This Row],[仕入単価+国内送料]] | Y20: 0.08 | Z20: 1年 | AA20: 常温 | AB20: 7日 | AC20: 4595430036034 | AD20: チセガーデンで育ったハーブを使ったハーブティーです。紫色のハーブティーですが、そのまま飲めば豊かな香りを楽しめます。レモン果汁を一滴入れるとピンク色に変わり、程よい酸味になります。 | AF20: 〇
A21: 菓子 | B21: 洋菓子 | C21: CHISE GARDEN | D21: ="PRD_SNJ_"& _xlfn.XLOOKUP(商品マスタ[[#This Row],[仕入先]],テーブル1[仕入先名],テーブル1[仕入先コード],"XXX",0,1)& "_"& 商品マスタ[[#This Row],[シリアル]]& "_"& TEXT(COUNTIFS(商品マスタ!$C$3:C21,商品マスタ[[#This Row],[仕入先]],商品マスタ!$E$3:E21,商品マスタ[[#This Row],[商品名]]), "00") | E21: 松葉仙人茶 | F21: =IF(COUNTIFS($C$3:C21,商品マスタ[[#This Row],[仕入先]],$E$3:E21,商品マスタ[[#This Row],[商品名]]) = 1, 1,0) | G21: =TEXT(SUMIF($C$3:C21,商品マスタ[[#This Row],[仕入先]],$F$3:F21), "0000") | H21: 袋 | I21: 8g×４/袋 | J21: 50 | L21: 700 | M21: 45951 | N21: 1080 | O21: =IF(COUNT(商品マスタ[[#This Row],[参考上代 （税込)]]) > 0, (商品マスタ[[#This Row],[参考上代 （税込)]]-商品マスタ[[#This Row],[国内定価 （15％）]])/(商品マスタ[[#This Row],[参考上代 （税込)]]/1.08), "") | P21: 0.1 | Q21: =商品マスタ[[#This Row],[仕入 単価]]*商品マスタ[[#This Row],[標準国内送料率]] | R21: 1000 | S21: =IF(ISBLANK(商品マスタ[[#This Row],[実績 国内送料]]),商品マスタ[[#This Row],[標準国内送料]],) | T21: =商品マスタ[[#This Row],[仕入 単価]]+商品マスタ[[#This Row],[国内送料]] | U21: =ROUNDUP(商品マスタ[[#This Row],[仕入単価+国内送料]]/0.8,-1) | V21: =商品マスタ[[#This Row],[海外定価 （20％）]]-商品マスタ[[#This Row],[仕入単価+国内送料]] | W21: =ROUNDUP(商品マスタ[[#This Row],[仕入単価+国内送料]]/0.85,-1) | X21: =商品マスタ[[#This Row],[国内定価 （15％）]]-商品マスタ[[#This Row],[仕入単価+国内送料]] | Y21: 0.08 | Z21: 1年 | AA21: 常温 | AB21: 7日 | AC21: 4595430036027 | AD21: 松葉仙人茶は、ニセコ産の高品質な松葉と高級なカバノアナタケを使用した贅沢な飲料です。この特別なブレンドには、またたび、松ぼっくり、桑の葉、そして三年番茶が含まれており、風味豊かな味わいを楽しむことができます。松葉仙人茶は健康的でリフレッシュすることができる飲み物です。贈り物や自分へのご褒美としても最適な一品です。 | AF21: 〇
A22: その他 | B22: 調味料 | C22: にんにく種蔵 | D22: ="PRD_SNJ_"& _xlfn.XLOOKUP(商品マスタ[[#This Row],[仕入先]],テーブル1[仕入先名],テーブル1[仕入先コード],"XXX",0,1)& "_"& 商品マスタ[[#This Row],[シリアル]]& "_"& TEXT(COUNTIFS(商品マスタ!$C$3:C22,商品マスタ[[#This Row],[仕入先]],商品マスタ!$E$3:E22,商品マスタ[[#This Row],[商品名]]), "00") | E22: ダイヤモンドにんにくマヨネーズ (瓶) | F22: =IF(COUNTIFS($C$3:C22,商品マスタ[[#This Row],[仕入先]],$E$3:E22,商品マスタ[[#This Row],[商品名]]) = 1, 1,0) | G22: =TEXT(SUMIF($C$3:C22,商品マスタ[[#This Row],[仕入先]],$F$3:F22), "0000") | H22: 瓶 | I22: 90g | J22: 30 | L22: =492/1.08 | M22: 45951 | N22: 850 | O22: =IF(COUNT(商品マスタ[[#This Row],[参考上代 （税込)]]) > 0, (商品マスタ[[#This Row],[参考上代 （税込)]]-商品マスタ[[#This Row],[国内定価 （15％）]])/(商品マスタ[[#This Row],[参考上代 （税込)]]/1.08), "") | P22: 0.1 | Q22: =商品マスタ[[#This Row],[仕入 単価]]*商品マスタ[[#This Row],[標準国内送料率]] | R22: 2050 | S22: =IF(ISBLANK(商品マスタ[[#This Row],[実績 国内送料]]),商品マスタ[[#This Row],[標準国内送料]],) | T22: =商品マスタ[[#This Row],[仕入 単価]]+商品マスタ[[#This Row],[国内送料]] | U22: =ROUNDUP(商品マスタ[[#This Row],[仕入単価+国内送料]]/0.8,-1) | V22: =商品マスタ[[#This Row],[海外定価 （20％）]]-商品マスタ[[#This Row],[仕入単価+国内送料]] | W22: =ROUNDUP(商品マスタ[[#This Row],[仕入単価+国内送料]]/0.85,-1) | X22: =商品マスタ[[#This Row],[国内定価 （15％）]]-商品マスタ[[#This Row],[仕入単価+国内送料]] | Y22: 0.08 | AC22: 4573252030331 | AD22: マツコの知らない世界で紹介。北海道美瑛町の自社農園でオリジナルブランド「北海道のダイヤモンドにんにく」を１００％使用したにんにくマヨネーズです。 | AF22: 〇
A23: その他 | B23: 調味料 | C23: にんにく種蔵 | D23: ="PRD_SNJ_"& _xlfn.XLOOKUP(商品マスタ[[#This Row],[仕入先]],テーブル1[仕入先名],テーブル1[仕入先コード],"XXX",0,1)& "_"& 商品マスタ[[#This Row],[シリアル]]& "_"& TEXT(COUNTIFS(商品マスタ!$C$3:C23,商品マスタ[[#This Row],[仕入先]],商品マスタ!$E$3:E23,商品マスタ[[#This Row],[商品名]]), "00") | E23: ダイヤモンドにんにくマヨネーズ (瓶) | F23: =IF(COUNTIFS($C$3:C23,商品マスタ[[#This Row],[仕入先]],$E$3:E23,商品マスタ[[#This Row],[商品名]]) = 1, 1,0) | G23: =TEXT(SUMIF($C$3:C23,商品マスタ[[#This Row],[仕入先]],$F$3:F23), "0000") | H23: 瓶 | I23: 90g | J23: 60 | L23: =492/1.08 | M23: 45951 | N23: 850 | O23: =IF(COUNT(商品マスタ[[#This Row],[参考上代 （税込)]]) > 0, (商品マスタ[[#This Row],[参考上代 （税込)]]-商品マスタ[[#This Row],[国内定価 （15％）]])/(商品マスタ[[#This Row],[参考上代 （税込)]]/1.08), "") | P23: 0.1 | Q23: =商品マスタ[[#This Row],[仕入 単価]]*商品マスタ[[#This Row],[標準国内送料率]] | R23: 2300 | S23: =IF(ISBLANK(商品マスタ[[#This Row],[実績 国内送料]]),商品マスタ[[#This Row],[標準国内送料]],) | T23: =商品マスタ[[#This Row],[仕入 単価]]+商品マスタ[[#This Row],[国内送料]] | U23: =ROUNDUP(商品マスタ[[#This Row],[仕入単価+国内送料]]/0.8,-1) | V23: =商品マスタ[[#This Row],[海外定価 （20％）]]-商品マスタ[[#This Row],[仕入単価+国内送料]] | W23: =ROUNDUP(商品マスタ[[#This Row],[仕入単価+国内送料]]/0.85,-1) | X23: =商品マスタ[[#This Row],[国内定価 （15％）]]-商品マスタ[[#This Row],[仕入単価+国内送料]] | Y23: 0.08 | AC23: 4573252030331 | AD23: マツコの知らない世界で紹介。北海道美瑛町の自社農園でオリジナルブランド「北海道のダイヤモンドにんにく」を１００％使用したにんにくマヨネーズです。 | AF23: 〇
A24: その他 | B24: 調味料 | C24: にんにく種蔵 | D24: ="PRD_SNJ_"& _xlfn.XLOOKUP(商品マスタ[[#This Row],[仕入先]],テーブル1[仕入先名],テーブル1[仕入先コード],"XXX",0,1)& "_"& 商品マスタ[[#This Row],[シリアル]]& "_"& TEXT(COUNTIFS(商品マスタ!$C$3:C24,商品マスタ[[#This Row],[仕入先]],商品マスタ!$E$3:E24,商品マスタ[[#This Row],[商品名]]), "00") | E24: ダイヤモンドにんにくマヨネーズ (パウチ) | F24: =IF(COUNTIFS($C$3:C24,商品マスタ[[#This Row],[仕入先]],$E$3:E24,商品マスタ[[#This Row],[商品名]]) = 1, 1,0) | G24: =TEXT(SUMIF($C$3:C24,商品マスタ[[#This Row],[仕入先]],$F$3:F24), "0000") | H24: パウチ | I24: 200g | J24: 50 | L24: 925 | M24: 45951 | N24: 1706 | O24: =IF(COUNT(商品マスタ[[#This Row],[参考上代 （税込)]]) > 0, (商品マスタ[[#This Row],[参考上代 （税込)]]-商品マスタ[[#This Row],[国内定価 （15％）]])/(商品マスタ[[#This Row],[参考上代 （税込)]]/1.08), "") | P24: 0.1 | Q24: =商品マスタ[[#This Row],[仕入 単価]]*商品マスタ[[#This Row],[標準国内送料率]] | S24: =IF(ISBLANK(商品マスタ[[#This Row],[実績 国内送料]]),商品マスタ[[#This Row],[標準国内送料]],) | T24: =商品マスタ[[#This Row],[仕入 単価]]+商品マスタ[[#This Row],[国内送料]] | U24: =ROUNDUP(商品マスタ[[#This Row],[仕入単価+国内送料]]/0.8,-1) | V24: =商品マスタ[[#This Row],[海外定価 （20％）]]-商品マスタ[[#This Row],[仕入単価+国内送料]] | W24: =ROUNDUP(商品マスタ[[#This Row],[仕入単価+国内送料]]/0.85,-1) | X24: =商品マスタ[[#This Row],[国内定価 （15％）]]-商品マスタ[[#This Row],[仕入単価+国内送料]] | Y24: 0.08 | AD24: マツコの知らない世界で紹介。北海道美瑛町の自社農園でオリジナルブランド「北海道のダイヤモンドにんにく」を１００％使用したにんにくマヨネーズのお徳用 パウチタイプです。 | AF24: 〇
A25: その他 | B25: 調味料 | C25: にんにく種蔵 | D25: ="PRD_SNJ_"& _xlfn.XLOOKUP(商品マスタ[[#This Row],[仕入先]],テーブル1[仕入先名],テーブル1[仕入先コード],"XXX",0,1)& "_"& 商品マスタ[[#This Row],[シリアル]]& "_"& TEXT(COUNTIFS(商品マスタ!$C$3:C25,商品マスタ[[#This Row],[仕入先]],商品マスタ!$E$3:E25,商品マスタ[[#This Row],[商品名]]), "00") | E25: ダイヤモンドにんにくマヨネーズ (パウチ) | F25: =IF(COUNTIFS($C$3:C25,商品マスタ[[#This Row],[仕入先]],$E$3:E25,商品マスタ[[#This Row],[商品名]]) = 1, 1,0) | G25: =TEXT(SUMIF($C$3:C25,商品マスタ[[#This Row],[仕入先]],$F$3:F25), "0000") | H25: パウチ | I25: 200g | J25: 100 | L25: 925 | M25: 45951 | N25: 1706 | O25: =IF(COUNT(商品マスタ[[#This Row],[参考上代 （税込)]]) > 0, (商品マスタ[[#This Row],[参考上代 （税込)]]-商品マスタ[[#This Row],[国内定価 （15％）]])/(商品マスタ[[#This Row],[参考上代 （税込)]]/1.08), "") | P25: 0.1 | Q25: =商品マスタ[[#This Row],[仕入 単価]]*商品マスタ[[#This Row],[標準国内送料率]] | S25: =IF(ISBLANK(商品マスタ[[#This Row],[実績 国内送料]]),商品マスタ[[#This Row],[標準国内送料]],) | T25: =商品マスタ[[#This Row],[仕入 単価]]+商品マスタ[[#This Row],[国内送料]] | U25: =ROUNDUP(商品マスタ[[#This Row],[仕入単価+国内送料]]/0.8,-1) | V25: =商品マスタ[[#This Row],[海外定価 （20％）]]-商品マスタ[[#This Row],[仕入単価+国内送料]] | W25: =ROUNDUP(商品マスタ[[#This Row],[仕入単価+国内送料]]/0.85,-1) | X25: =商品マスタ[[#This Row],[国内定価 （15％）]]-商品マスタ[[#This Row],[仕入単価+国内送料]] | Y25: 0.08 | AD25: マツコの知らない世界で紹介。北海道美瑛町の自社農園でオリジナルブランド「北海道のダイヤモンドにんにく」を１００％使用したにんにくマヨネーズのお徳用 パウチタイプです。 | AF25: 〇
A26: その他 | B26: 調味料 | C26: にんにく種蔵 | D26: ="PRD_SNJ_"& _xlfn.XLOOKUP(商品マスタ[[#This Row],[仕入先]],テーブル1[仕入先名],テーブル1[仕入先コード],"XXX",0,1)& "_"& 商品マスタ[[#This Row],[シリアル]]& "_"& TEXT(COUNTIFS(商品マスタ!$C$3:C26,商品マスタ[[#This Row],[仕入先]],商品マスタ!$E$3:E26,商品マスタ[[#This Row],[商品名]]), "00") | E26: 【数量限定】ダイヤモンドにんにくオリーブオイル | F26: =IF(COUNTIFS($C$3:C26,商品マスタ[[#This Row],[仕入先]],$E$3:E26,商品マスタ[[#This Row],[商品名]]) = 1, 1,0) | G26: =TEXT(SUMIF($C$3:C26,商品マスタ[[#This Row],[仕入先]],$F$3:F26), "0000") | H26: 瓶 | I26: ml | J26: 48 | K26: 1c/s48本 | L26: 1714 | M26: 45951 | N26: 2678 | O26: =IF(COUNT(商品マスタ[[#This Row],[参考上代 （税込)]]) > 0, (商品マスタ[[#This Row],[参考上代 （税込)]]-商品マスタ[[#This Row],[国内定価 （15％）]])/(商品マスタ[[#This Row],[参考上代 （税込)]]/1.08), "") | P26: 0.1 | Q26: =商品マスタ[[#This Row],[仕入 単価]]*商品マスタ[[#This Row],[標準国内送料率]] | S26: =IF(ISBLANK(商品マスタ[[#This Row],[実績 国内送料]]),商品マスタ[[#This Row],[標準国内送料]],) | T26: =商品マスタ[[#This Row],[仕入 単価]]+商品マスタ[[#This Row],[国内送料]] | U26: =ROUNDUP(商品マスタ[[#This Row],[仕入単価+国内送料]]/0.8,-1) | V26: =商品マスタ[[#This Row],[海外定価 （20％）]]-商品マスタ[[#This Row],[仕入単価+国内送料]] | W26: =ROUNDUP(商品マスタ[[#This Row],[仕入単価+国内送料]]/0.85,-1) | X26: =商品マスタ[[#This Row],[国内定価 （15％）]]-商品マスタ[[#This Row],[仕入単価+国内送料]] | Y26: 0.08 | AC26: 4595318851063 | AD26: 美瑛の自社農園で丁寧に作られた、農薬・化学肥料不使用のダイヤモンドにんにくをオリーブオイルにしました。オリーブオイルは本場イタリア産を使用。えぐみがなく香り高い特徴がこのオリーブオイルとよく馴染んでいます。 | AF26: ✕ | AG26: 要在庫確認。数量限定。発送元が異なるため 別途送料必要
A27: その他 | B27: 調味料 | C27: にんにく種蔵 | D27: ="PRD_SNJ_"& _xlfn.XLOOKUP(商品マスタ[[#This Row],[仕入先]],テーブル1[仕入先名],テーブル1[仕入先コード],"XXX",0,1)& "_"& 商品マスタ[[#This Row],[シリアル]]& "_"& TEXT(COUNTIFS(商品マスタ!$C$3:C27,商品マスタ[[#This Row],[仕入先]],商品マスタ!$E$3:E27,商品マスタ[[#This Row],[商品名]]), "00") | E27: ダイヤモンドにんにく味噌 | F27: =IF(COUNTIFS($C$3:C27,商品マスタ[[#This Row],[仕入先]],$E$3:E27,商品マスタ[[#This Row],[商品名]]) = 1, 1,0) | G27: =TEXT(SUMIF($C$3:C27,商品マスタ[[#This Row],[仕入先]],$F$3:F27), "0000") | H27: 瓶 | I27: 110g | J27: 60 | L27: 456 | M27: 45951 | N27: 850 | O27: =IF(COUNT(商品マスタ[[#This Row],[参考上代 （税込)]]) > 0, (商品マスタ[[#This Row],[参考上代 （税込)]]-商品マスタ[[#This Row],[国内定価 （15％）]])/(商品マスタ[[#This Row],[参考上代 （税込)]]/1.08), "") | P27: 0.1 | Q27: =商品マスタ[[#This Row],[仕入 単価]]*商品マスタ[[#This Row],[標準国内送料率]] | S27: =IF(ISBLANK(商品マスタ[[#This Row],[実績 国内送料]]),商品マスタ[[#This Row],[標準国内送料]],) | T27: =商品マスタ[[#This Row],[仕入 単価]]+商品マスタ[[#This Row],[国内送料]] | U27: =ROUNDUP(商品マスタ[[#This Row],[仕入単価+国内送料]]/0.8,-1) | V27: =商品マスタ[[#This Row],[海外定価 （20％）]]-商品マスタ[[#This Row],[仕入単価+国内送料]] | W27: =ROUNDUP(商品マスタ[[#This Row],[仕入単価+国内送料]]/0.85,-1) | X27: =商品マスタ[[#This Row],[国内定価 （15％）]]-商品マスタ[[#This Row],[仕入単価+国内送料]] | Y27: 0.08 | AD27: 美瑛にある自社農園で農薬・化学肥料不使用で愛情込めて作られたダイヤモンドにんにくを味噌にしました。 | AF27: 〇
A28: その他 | B28: 調味料 | C28: にんにく種蔵 | D28: ="PRD_SNJ_"& _xlfn.XLOOKUP(商品マスタ[[#This Row],[仕入先]],テーブル1[仕入先名],テーブル1[仕入先コード],"XXX",0,1)& "_"& 商品マスタ[[#This Row],[シリアル]]& "_"& TEXT(COUNTIFS(商品マスタ!$C$3:C28,商品マスタ[[#This Row],[仕入先]],商品マスタ!$E$3:E28,商品マスタ[[#This Row],[商品名]]), "00") | E28: ダイヤモンドにんにくバーニャカウダ | F28: =IF(COUNTIFS($C$3:C28,商品マスタ[[#This Row],[仕入先]],$E$3:E28,商品マスタ[[#This Row],[商品名]]) = 1, 1,0) | G28: =TEXT(SUMIF($C$3:C28,商品マスタ[[#This Row],[仕入先]],$F$3:F28), "0000") | H28: 瓶 | I28: 90g | J28: 60 | L28: 456 | M28: 45951 | N28: 850 | O28: =IF(COUNT(商品マスタ[[#This Row],[参考上代 （税込)]]) > 0, (商品マスタ[[#This Row],[参考上代 （税込)]]-商品マスタ[[#This Row],[国内定価 （15％）]])/(商品マスタ[[#This Row],[参考上代 （税込)]]/1.08), "") | P28: 0.1 | Q28: =商品マスタ[[#This Row],[仕入 単価]]*商品マスタ[[#This Row],[標準国内送料率]] | S28: =IF(ISBLANK(商品マスタ[[#This Row],[実績 国内送料]]),商品マスタ[[#This Row],[標準国内送料]],) | T28: =商品マスタ[[#This Row],[仕入 単価]]+商品マスタ[[#This Row],[国内送料]] | U28: =ROUNDUP(商品マスタ[[#This Row],[仕入単価+国内送料]]/0.8,-1) | V28: =商品マスタ[[#This Row],[海外定価 （20％）]]-商品マスタ[[#This Row],[仕入単価+国内送料]] | W28: =ROUNDUP(商品マスタ[[#This Row],[仕入単価+国内送料]]/0.85,-1) | X28: =商品マスタ[[#This Row],[国内定価 （15％）]]-商品マスタ[[#This Row],[仕入単価+国内送料]] | Y28: 0.08 | AD28: アンチョビが効いていて隠し味のココナッツミルクが程よいマイルド感を出してくれます。 ダイヤモンドにんにくの旨みもたっぷり入っています。 | AF28: 〇
A29: その他 | B29: 調味料 | C29: にんにく種蔵 | D29: ="PRD_SNJ_"& _xlfn.XLOOKUP(商品マスタ[[#This Row],[仕入先]],テーブル1[仕入先名],テーブル1[仕入先コード],"XXX",0,1)& "_"& 商品マスタ[[#This Row],[シリアル]]& "_"& TEXT(COUNTIFS(商品マスタ!$C$3:C29,商品マスタ[[#This Row],[仕入先]],商品マスタ!$E$3:E29,商品マスタ[[#This Row],[商品名]]), "00") | E29: 絶望のにんにくトマトソース200g | F29: =IF(COUNTIFS($C$3:C29,商品マスタ[[#This Row],[仕入先]],$E$3:E29,商品マスタ[[#This Row],[商品名]]) = 1, 1,0) | G29: =TEXT(SUMIF($C$3:C29,商品マスタ[[#This Row],[仕入先]],$F$3:F29), "0000") | H29: パウチ | I29: 200g | J29: 100 | K29: 1c/s50個 | L29: 456 | M29: 45951 | N29: 853 | O29: =IF(COUNT(商品マスタ[[#This Row],[参考上代 （税込)]]) > 0, (商品マスタ[[#This Row],[参考上代 （税込)]]-商品マスタ[[#This Row],[国内定価 （15％）]])/(商品マスタ[[#This Row],[参考上代 （税込)]]/1.08), "") | P29: 0.1 | Q29: =商品マスタ[[#This Row],[仕入 単価]]*商品マスタ[[#This Row],[標準国内送料率]] | S29: =IF(ISBLANK(商品マスタ[[#This Row],[実績 国内送料]]),商品マスタ[[#This Row],[標準国内送料]],) | T29: =商品マスタ[[#This Row],[仕入 単価]]+商品マスタ[[#This Row],[国内送料]] | U29: =ROUNDUP(商品マスタ[[#This Row],[仕入単価+国内送料]]/0.8,-1) | V29: =商品マスタ[[#This Row],[海外定価 （20％）]]-商品マスタ[[#This Row],[仕入単価+国内送料]] | W29: =ROUNDUP(商品マスタ[[#This Row],[仕入単価+国内送料]]/0.85,-1) | X29: =商品マスタ[[#This Row],[国内定価 （15％）]]-商品マスタ[[#This Row],[仕入単価+国内送料]] | Y29: 0.08 | AD29: 濃厚なトマトソースに程よいピリ辛＆ガツンと効いたにんにくが最高！茹でたパスタに混ぜるだけで本格トマトパスタが味わえます。 | AF29: 〇
A30: その他 | B30: 調味料 | C30: にんにく種蔵 | D30: ="PRD_SNJ_"& _xlfn.XLOOKUP(商品マスタ[[#This Row],[仕入先]],テーブル1[仕入先名],テーブル1[仕入先コード],"XXX",0,1)& "_"& 商品マスタ[[#This Row],[シリアル]]& "_"& TEXT(COUNTIFS(商品マスタ!$C$3:C30,商品マスタ[[#This Row],[仕入先]],商品マスタ!$E$3:E30,商品マスタ[[#This Row],[商品名]]), "00") | E30: 待望のにんにくペペロンチーノソース200g | F30: =IF(COUNTIFS($C$3:C30,商品マスタ[[#This Row],[仕入先]],$E$3:E30,商品マスタ[[#This Row],[商品名]]) = 1, 1,0) | G30: =TEXT(SUMIF($C$3:C30,商品マスタ[[#This Row],[仕入先]],$F$3:F30), "0000") | H30: パウチ | I30: 200g | J30: 100 | K30: 1c/s50個 | L30: 456 | M30: 45951 | N30: 853 | O30: =IF(COUNT(商品マスタ[[#This Row],[参考上代 （税込)]]) > 0, (商品マスタ[[#This Row],[参考上代 （税込)]]-商品マスタ[[#This Row],[国内定価 （15％）]])/(商品マスタ[[#This Row],[参考上代 （税込)]]/1.08), "") | P30: 0.1 | Q30: =商品マスタ[[#This Row],[仕入 単価]]*商品マスタ[[#This Row],[標準国内送料率]] | S30: =IF(ISBLANK(商品マスタ[[#This Row],[実績 国内送料]]),商品マスタ[[#This Row],[標準国内送料]],) | T30: =商品マスタ[[#This Row],[仕入 単価]]+商品マスタ[[#This Row],[国内送料]] | U30: =ROUNDUP(商品マスタ[[#This Row],[仕入単価+国内送料]]/0.8,-1) | V30: =商品マスタ[[#This Row],[海外定価 （20％）]]-商品マスタ[[#This Row],[仕入単価+国内送料]] | W30: =ROUNDUP(商品マスタ[[#This Row],[仕入単価+国内送料]]/0.85,-1) | X30: =商品マスタ[[#This Row],[国内定価 （15％）]]-商品マスタ[[#This Row],[仕入単価+国内送料]] | Y30: 0.08 | AD30: にんにく満足宣言！！これこそ探し求めていた混ぜるだけで激うまペペロンチーノ！パスタに絡まるガツンとにんにく&ブラックペッパーなどのスパイスが絶妙なバランス。チャーハンの仕上げにもおすすめです！ | AF30: 〇
A31: その他 | B31: 調味料 | C31: 白亜ダイシン | D31: ="PRD_SNJ_"& _xlfn.XLOOKUP(商品マスタ[[#This Row],[仕入先]],テーブル1[仕入先名],テーブル1[仕入先コード],"XXX",0,1)& "_"& 商品マスタ[[#This Row],[シリアル]]& "_"& TEXT(COUNTIFS(商品マスタ!$C$3:C31,商品マスタ[[#This Row],[仕入先]],商品マスタ!$E$3:E31,商品マスタ[[#This Row],[商品名]]), "00") | E31: 北海道アールグレイミルクジャム | F31: =IF(COUNTIFS($C$3:C31,商品マスタ[[#This Row],[仕入先]],$E$3:E31,商品マスタ[[#This Row],[商品名]]) = 1, 1,0) | G31: =TEXT(SUMIF($C$3:C31,商品マスタ[[#This Row],[仕入先]],$F$3:F31), "0000") | H31: 瓶 | I31: 140ｇ | J31: 12 | L31: 450 | M31: 45952 | N31: 750 | O31: =IF(COUNT(商品マスタ[[#This Row],[参考上代 （税込)]]) > 0, (商品マスタ[[#This Row],[参考上代 （税込)]]-商品マスタ[[#This Row],[国内定価 （15％）]])/(商品マスタ[[#This Row],[参考上代 （税込)]]/1.08), "") | P31: 0.1 | Q31: =商品マスタ[[#This Row],[仕入 単価]]*商品マスタ[[#This Row],[標準国内送料率]] | R31: 1280 | S31: =IF(ISBLANK(商品マスタ[[#This Row],[実績 国内送料]]),商品マスタ[[#This Row],[標準国内送料]],) | T31: =商品マスタ[[#This Row],[仕入 単価]]+商品マスタ[[#This Row],[国内送料]] | U31: =ROUNDUP(商品マスタ[[#This Row],[仕入単価+国内送料]]/0.8,-1) | V31: =商品マスタ[[#This Row],[海外定価 （20％）]]-商品マスタ[[#This Row],[仕入単価+国内送料]] | W31: =ROUNDUP(商品マスタ[[#This Row],[仕入単価+国内送料]]/0.85,-1) | X31: =商品マスタ[[#This Row],[国内定価 （15％）]]-商品マスタ[[#This Row],[仕入単価+国内送料]] | Y31: 0.08 | Z31: 8日 | AA31: 常温 | AC31: 4562182193957 | AD31: 北海道産の新鮮なミルクをたっぷりと使用し、なめらかで濃厚な口当たりに仕上げたミルクジャムに、香り高いアールグレイの茶葉を贅沢に加えました。アールグレイ特有の柑橘系の華やかな香りがミルクのコクと絶妙に調和し、紅茶の風味が引き立つ上品な味わいが楽しめます。ミルクの優しい甘さと、アールグレイの爽やかで芳醇な香りが織りなすハーモニーは、一口食べるたびにティータイムのような心地よさを感じさせてくれます。 | AF31: 〇
A32: その他 | B32: 調味料 | C32: 白亜ダイシン | D32: ="PRD_SNJ_"& _xlfn.XLOOKUP(商品マスタ[[#This Row],[仕入先]],テーブル1[仕入先名],テーブル1[仕入先コード],"XXX",0,1)& "_"& 商品マスタ[[#This Row],[シリアル]]& "_"& TEXT(COUNTIFS(商品マスタ!$C$3:C32,商品マスタ[[#This Row],[仕入先]],商品マスタ!$E$3:E32,商品マスタ[[#This Row],[商品名]]), "00") | E32: 北海道ほうじ茶ミルクジャム | F32: =IF(COUNTIFS($C$3:C32,商品マスタ[[#This Row],[仕入先]],$E$3:E32,商品マスタ[[#This Row],[商品名]]) = 1, 1,0) | G32: =TEXT(SUMIF($C$3:C32,商品マスタ[[#This Row],[仕入先]],$F$3:F32), "0000") | H32: 袋 | I32: 140ｇ | J32: 12 | L32: 450 | M32: 45952 | N32: 750 | O32: =IF(COUNT(商品マスタ[[#This Row],[参考上代 （税込)]]) > 0, (商品マスタ[[#This Row],[参考上代 （税込)]]-商品マスタ[[#This Row],[国内定価 （15％）]])/(商品マスタ[[#This Row],[参考上代 （税込)]]/1.08), "") | P32: 0.1 | Q32: =商品マスタ[[#This Row],[仕入 単価]]*商品マスタ[[#This Row],[標準国内送料率]] | R32: 1280 | S32: =IF(ISBLANK(商品マスタ[[#This Row],[実績 国内送料]]),商品マスタ[[#This Row],[標準国内送料]],) | T32: =商品マスタ[[#This Row],[仕入 単価]]+商品マスタ[[#This Row],[国内送料]] | U32: =ROUNDUP(商品マスタ[[#This Row],[仕入単価+国内送料]]/0.8,-1) | V32: =商品マスタ[[#This Row],[海外定価 （20％）]]-商品マスタ[[#This Row],[仕入単価+国内送料]] | W32: =ROUNDUP(商品マスタ[[#This Row],[仕入単価+国内送料]]/0.85,-1) | X32: =商品マスタ[[#This Row],[国内定価 （15％）]]-商品マスタ[[#This Row],[仕入単価+国内送料]] | Y32: 0.08 | Z32: 8日 | AA32: 常温 | AC32: 4562182193940 | AD32: 北海道産の新鮮なミルクをたっぷりと贅沢に使用し、濃厚でなめらかな味わいに仕上げたミルクジャムに、国産のほうじ茶の茶葉を細かく挽いた細粒を加えました。ほうじ茶特有の香ばしく、深みのある風味がミルクのコクと見事に調和し、口に入れた瞬間にふわっと広がる豊かな香りが楽しめます。香ばしいほうじ茶の香りと、優しい甘さのミルクジャムが織りなす絶妙なハーモニーは、まるで和のティータイムを味わっているかのような上品な味わいを演出します。 | AF32: 〇
A33: 菓子 | B33: 和菓子 | C33: 白亜ダイシン | D33: ="PRD_SNJ_"& _xlfn.XLOOKUP(商品マスタ[[#This Row],[仕入先]],テーブル1[仕入先名],テーブル1[仕入先コード],"XXX",0,1)& "_"& 商品マスタ[[#This Row],[シリアル]]& "_"& TEXT(COUNTIFS(商品マスタ!$C$3:C33,商品マスタ[[#This Row],[仕入先]],商品マスタ!$E$3:E33,商品マスタ[[#This Row],[商品名]]), "00") | E33: ミルクキャンディ | F33: =IF(COUNTIFS($C$3:C33,商品マスタ[[#This Row],[仕入先]],$E$3:E33,商品マスタ[[#This Row],[商品名]]) = 1, 1,0) | G33: =TEXT(SUMIF($C$3:C33,商品マスタ[[#This Row],[仕入先]],$F$3:F33), "0000") | H33: 袋 | I33: 60ｇ | J33: 40 | L33: 228 | M33: 45952 | N33: 380 | O33: =IF(COUNT(商品マスタ[[#This Row],[参考上代 （税込)]]) > 0, (商品マスタ[[#This Row],[参考上代 （税込)]]-商品マスタ[[#This Row],[国内定価 （15％）]])/(商品マスタ[[#This Row],[参考上代 （税込)]]/1.08), "") | P33: 0.1 | Q33: =商品マスタ[[#This Row],[仕入 単価]]*商品マスタ[[#This Row],[標準国内送料率]] | R33: 1280 | S33: =IF(ISBLANK(商品マスタ[[#This Row],[実績 国内送料]]),商品マスタ[[#This Row],[標準国内送料]],) | T33: =商品マスタ[[#This Row],[仕入 単価]]+商品マスタ[[#This Row],[国内送料]] | U33: =ROUNDUP(商品マスタ[[#This Row],[仕入単価+国内送料]]/0.8,-1) | V33: =商品マスタ[[#This Row],[海外定価 （20％）]]-商品マスタ[[#This Row],[仕入単価+国内送料]] | W33: =ROUNDUP(商品マスタ[[#This Row],[仕入単価+国内送料]]/0.85,-1) | X33: =商品マスタ[[#This Row],[国内定価 （15％）]]-商品マスタ[[#This Row],[仕入単価+国内送料]] | Y33: 0.08 | Z33: 8日 | AA33: 常温 | AC33: 4562182194787 | AD33: 濃厚なミルクをたっぷりと使用し、なめらかでコクのある味わいに仕上げました。口に入れた瞬間に広がるやさしい甘さと、じんわりと溶けていくミルクの風味が、まるでおとぎ話の世界に迷い込んだかのような心温まるひとときを演出します。 | AF33: 〇
A34: 菓子 | B34: 和菓子 | C34: 白亜ダイシン | D34: ="PRD_SNJ_"& _xlfn.XLOOKUP(商品マスタ[[#This Row],[仕入先]],テーブル1[仕入先名],テーブル1[仕入先コード],"XXX",0,1)& "_"& 商品マスタ[[#This Row],[シリアル]]& "_"& TEXT(COUNTIFS(商品マスタ!$C$3:C34,商品マスタ[[#This Row],[仕入先]],商品マスタ!$E$3:E34,商品マスタ[[#This Row],[商品名]]), "00") | E34: ミントキャンディ | F34: =IF(COUNTIFS($C$3:C34,商品マスタ[[#This Row],[仕入先]],$E$3:E34,商品マスタ[[#This Row],[商品名]]) = 1, 1,0) | G34: =TEXT(SUMIF($C$3:C34,商品マスタ[[#This Row],[仕入先]],$F$3:F34), "0000") | H34: 袋 | I34: 60ｇ | J34: 40 | L34: 228 | M34: 45952 | N34: 380 | O34: =IF(COUNT(商品マスタ[[#This Row],[参考上代 （税込)]]) > 0, (商品マスタ[[#This Row],[参考上代 （税込)]]-商品マスタ[[#This Row],[国内定価 （15％）]])/(商品マスタ[[#This Row],[参考上代 （税込)]]/1.08), "") | P34: 0.1 | Q34: =商品マスタ[[#This Row],[仕入 単価]]*商品マスタ[[#This Row],[標準国内送料率]] | R34: 1280 | S34: =IF(ISBLANK(商品マスタ[[#This Row],[実績 国内送料]]),商品マスタ[[#This Row],[標準国内送料]],) | T34: =商品マスタ[[#This Row],[仕入 単価]]+商品マスタ[[#This Row],[国内送料]] | U34: =ROUNDUP(商品マスタ[[#This Row],[仕入単価+国内送料]]/0.8,-1) | V34: =商品マスタ[[#This Row],[海外定価 （20％）]]-商品マスタ[[#This Row],[仕入単価+国内送料]] | W34: =ROUNDUP(商品マスタ[[#This Row],[仕入単価+国内送料]]/0.85,-1) | X34: =商品マスタ[[#This Row],[国内定価 （15％）]]-商品マスタ[[#This Row],[仕入単価+国内送料]] | Y34: 0.08 | Z34: 8日 | AA34: 常温 | AC34: 4562182194794 | AD34: ひと口食べれば、すっきりとした清涼感が広がり、爽やかな風が吹き抜けるような心地よさを感じられます。口の中に広がるクールな味わいは、気分をリフレッシュしたいときや、ちょっとした息抜きの時間にもぴったり。厳選したミントの風味を活かし、ほどよい甘さと爽快感のバランスを絶妙に仕上げました。 | AF34: 〇
A35: その他 | B35: 備長炭 | C35: 白亜ダイシン | D35: ="PRD_SNJ_"& _xlfn.XLOOKUP(商品マスタ[[#This Row],[仕入先]],テーブル1[仕入先名],テーブル1[仕入先コード],"XXX",0,1)& "_"& 商品マスタ[[#This Row],[シリアル]]& "_"& TEXT(COUNTIFS(商品マスタ!$C$3:C35,商品マスタ[[#This Row],[仕入先]],商品マスタ!$E$3:E35,商品マスタ[[#This Row],[商品名]]), "00") | E35: ミックスベリーソーダ | F35: =IF(COUNTIFS($C$3:C35,商品マスタ[[#This Row],[仕入先]],$E$3:E35,商品マスタ[[#This Row],[商品名]]) = 1, 1,0) | G35: =TEXT(SUMIF($C$3:C35,商品マスタ[[#This Row],[仕入先]],$F$3:F35), "0000") | H35: 瓶 | I35: 200ml | J35: 24 | L35: 228 | M35: 45952 | N35: 380 | O35: =IF(COUNT(商品マスタ[[#This Row],[参考上代 （税込)]]) > 0, (商品マスタ[[#This Row],[参考上代 （税込)]]-商品マスタ[[#This Row],[国内定価 （15％）]])/(商品マスタ[[#This Row],[参考上代 （税込)]]/1.08), "") | P35: 0.1 | Q35: =商品マスタ[[#This Row],[仕入 単価]]*商品マスタ[[#This Row],[標準国内送料率]] | R35: 1280 | S35: =IF(ISBLANK(商品マスタ[[#This Row],[実績 国内送料]]),商品マスタ[[#This Row],[標準国内送料]],) | T35: =商品マスタ[[#This Row],[仕入 単価]]+商品マスタ[[#This Row],[国内送料]] | U35: =ROUNDUP(商品マスタ[[#This Row],[仕入単価+国内送料]]/0.8,-1) | V35: =商品マスタ[[#This Row],[海外定価 （20％）]]-商品マスタ[[#This Row],[仕入単価+国内送料]] | W35: =ROUNDUP(商品マスタ[[#This Row],[仕入単価+国内送料]]/0.85,-1) | X35: =商品マスタ[[#This Row],[国内定価 （15％）]]-商品マスタ[[#This Row],[仕入単価+国内送料]] | Y35: 0.08 | Z35: 8日 | AA35: 常温 | AC35: 4562182191731 | AD35: 北海道産のハスカップとはちみつをベースに、ラズベリーとカシスをバランスよくブレンドした、フルーティーな炭酸ドリンクです。ハスカップのほどよい酸味に、ラズベリーの華やかな香りとカシスの深みのあるコクが加わり、爽やかで飲みやすい味わいに仕上げました。炭酸の心地よい刺激が、口の中でふわっと広がるベリーの香りを引き立て、ほんのり甘くすっきりとした後味が楽しめます。 | AF35: 〇
A36: 菓子 | B36: 洋菓子 | C36: 白亜ダイシン | D36: ="PRD_SNJ_"& _xlfn.XLOOKUP(商品マスタ[[#This Row],[仕入先]],テーブル1[仕入先名],テーブル1[仕入先コード],"XXX",0,1)& "_"& 商品マスタ[[#This Row],[シリアル]]& "_"& TEXT(COUNTIFS(商品マスタ!$C$3:C36,商品マスタ[[#This Row],[仕入先]],商品マスタ!$E$3:E36,商品マスタ[[#This Row],[商品名]]), "00") | E36: 北海道バジルソース | F36: =IF(COUNTIFS($C$3:C36,商品マスタ[[#This Row],[仕入先]],$E$3:E36,商品マスタ[[#This Row],[商品名]]) = 1, 1,0) | G36: =TEXT(SUMIF($C$3:C36,商品マスタ[[#This Row],[仕入先]],$F$3:F36), "0000") | H36: 瓶 | I36: 110ｇ | J36: 12 | L36: 504 | M36: 45952 | N36: 840 | O36: =IF(COUNT(商品マスタ[[#This Row],[参考上代 （税込)]]) > 0, (商品マスタ[[#This Row],[参考上代 （税込)]]-商品マスタ[[#This Row],[国内定価 （15％）]])/(商品マスタ[[#This Row],[参考上代 （税込)]]/1.08), "") | P36: 0.1 | Q36: =商品マスタ[[#This Row],[仕入 単価]]*商品マスタ[[#This Row],[標準国内送料率]] | R36: 1280 | S36: =IF(ISBLANK(商品マスタ[[#This Row],[実績 国内送料]]),商品マスタ[[#This Row],[標準国内送料]],) | T36: =商品マスタ[[#This Row],[仕入 単価]]+商品マスタ[[#This Row],[国内送料]] | U36: =ROUNDUP(商品マスタ[[#This Row],[仕入単価+国内送料]]/0.8,-1) | V36: =商品マスタ[[#This Row],[海外定価 （20％）]]-商品マスタ[[#This Row],[仕入単価+国内送料]] | W36: =ROUNDUP(商品マスタ[[#This Row],[仕入単価+国内送料]]/0.85,-1) | X36: =商品マスタ[[#This Row],[国内定価 （15％）]]-商品マスタ[[#This Row],[仕入単価+国内送料]] | Y36: 0.08 | Z36: 8日 | AA36: 常温 | AC36: 4562182191687 | AD36: 北海道産のバジルだけを贅沢に使用した、シンプルでありながら王道のバジルソースが誕生しました。収穫したばかりの新鮮なバジルをたっぷりと使い、素材本来の風味を存分に引き出しています。そこにカシューナッツと粉チーズを加え、クセがなく、まろやかでコクのある味わいに仕上げました。 | AF36: 〇
A37: 青果 | B37: 野菜 | C37: 白亜ダイシン | D37: ="PRD_SNJ_"& _xlfn.XLOOKUP(商品マスタ[[#This Row],[仕入先]],テーブル1[仕入先名],テーブル1[仕入先コード],"XXX",0,1)& "_"& 商品マスタ[[#This Row],[シリアル]]& "_"& TEXT(COUNTIFS(商品マスタ!$C$3:C37,商品マスタ[[#This Row],[仕入先]],商品マスタ!$E$3:E37,商品マスタ[[#This Row],[商品名]]), "00") | E37: 北海道焼肉ソース | F37: =IF(COUNTIFS($C$3:C37,商品マスタ[[#This Row],[仕入先]],$E$3:E37,商品マスタ[[#This Row],[商品名]]) = 1, 1,0) | G37: =TEXT(SUMIF($C$3:C37,商品マスタ[[#This Row],[仕入先]],$F$3:F37), "0000") | H37: 瓶 | I37: 200ｇ | J37: 12 | L37: 414 | M37: 45952 | N37: 690 | O37: =IF(COUNT(商品マスタ[[#This Row],[参考上代 （税込)]]) > 0, (商品マスタ[[#This Row],[参考上代 （税込)]]-商品マスタ[[#This Row],[国内定価 （15％）]])/(商品マスタ[[#This Row],[参考上代 （税込)]]/1.08), "") | P37: 0.1 | Q37: =商品マスタ[[#This Row],[仕入 単価]]*商品マスタ[[#This Row],[標準国内送料率]] | R37: 1280 | S37: =IF(ISBLANK(商品マスタ[[#This Row],[実績 国内送料]]),商品マスタ[[#This Row],[標準国内送料]],) | T37: =商品マスタ[[#This Row],[仕入 単価]]+商品マスタ[[#This Row],[国内送料]] | U37: =ROUNDUP(商品マスタ[[#This Row],[仕入単価+国内送料]]/0.8,-1) | V37: =商品マスタ[[#This Row],[海外定価 （20％）]]-商品マスタ[[#This Row],[仕入単価+国内送料]] | W37: =ROUNDUP(商品マスタ[[#This Row],[仕入単価+国内送料]]/0.85,-1) | X37: =商品マスタ[[#This Row],[国内定価 （15％）]]-商品マスタ[[#This Row],[仕入単価+国内送料]] | Y37: 0.08 | Z37: 8日 | AA37: 常温 | AC37: 4562182192189 | AD37: 北海道産の風味豊かなしょうがをふんだんに使い、ピリッとした爽やかな辛味と香りが引き立つ焼肉ソースに仕上げました。ベースには、北海道産大豆を使用したまろやかでコクのある醤油を採用し、味に深みと奥行きをプラス。さらに、カットした北海道産玉ねぎをたっぷりと加えることで、甘みと旨みが増し、よりマイルドで後味すっきりとした味わいを実現しました。 | AF37: 〇
A38: 加工品 | B38: 肉加工品 | C38: シャルキュトリーアカイシ | D38: ="PRD_SNJ_"& _xlfn.XLOOKUP(商品マスタ[[#This Row],[仕入先]],テーブル1[仕入先名],テーブル1[仕入先コード],"XXX",0,1)& "_"& 商品マスタ[[#This Row],[シリアル]]& "_"& TEXT(COUNTIFS(商品マスタ!$C$3:C38,商品マスタ[[#This Row],[仕入先]],商品マスタ!$E$3:E38,商品マスタ[[#This Row],[商品名]]), "00") | E38: 豚バラ肉のベーコン（スライス）/ Poitrine fumée | F38: =IF(COUNTIFS($C$3:C38,商品マスタ[[#This Row],[仕入先]],$E$3:E38,商品マスタ[[#This Row],[商品名]]) = 1, 1,0) | G38: =TEXT(SUMIF($C$3:C38,商品マスタ[[#This Row],[仕入先]],$F$3:F38), "0000") | I38: 100ｇ | J38: 5 | L38: 625 | M38: 45952 | N38: 900 | O38: =IF(COUNT(商品マスタ[[#This Row],[参考上代 （税込)]]) > 0, (商品マスタ[[#This Row],[参考上代 （税込)]]-商品マスタ[[#This Row],[国内定価 （15％）]])/(商品マスタ[[#This Row],[参考上代 （税込)]]/1.08), "") | P38: 0.1 | Q38: =商品マスタ[[#This Row],[仕入 単価]]*商品マスタ[[#This Row],[標準国内送料率]] | S38: =IF(ISBLANK(商品マスタ[[#This Row],[実績 国内送料]]),商品マスタ[[#This Row],[標準国内送料]],) | T38: =商品マスタ[[#This Row],[仕入 単価]]+商品マスタ[[#This Row],[国内送料]] | U38: =ROUNDUP(商品マスタ[[#This Row],[仕入単価+国内送料]]/0.8,-1) | V38: =商品マスタ[[#This Row],[海外定価 （20％）]]-商品マスタ[[#This Row],[仕入単価+国内送料]] | W38: =ROUNDUP(商品マスタ[[#This Row],[仕入単価+国内送料]]/0.85,-1) | X38: =商品マスタ[[#This Row],[国内定価 （15％）]]-商品マスタ[[#This Row],[仕入単価+国内送料]] | Y38: 0.08 | Z38: 30日 | AA38: 10℃以下 | AB38: 5日 | AC38: 4580578380149 | AD38: 桜のチップでスモーク。熟成と燻煙で肉のうまみを凝縮したベーコン。そのまま焼いてベーコンエッグやサンドウィッチに。 | AF38: 〇 | AG38: 最優秀賞受賞商品。2万円以上の注文で送料無料。
A39: 加工品 | B39: 肉加工品 | C39: シャルキュトリーアカイシ | D39: ="PRD_SNJ_"& _xlfn.XLOOKUP(商品マスタ[[#This Row],[仕入先]],テーブル1[仕入先名],テーブル1[仕入先コード],"XXX",0,1)& "_"& 商品マスタ[[#This Row],[シリアル]]& "_"& TEXT(COUNTIFS(商品マスタ!$C$3:C39,商品マスタ[[#This Row],[仕入先]],商品マスタ!$E$3:E39,商品マスタ[[#This Row],[商品名]]), "00") | E39: 豚バラ肉のベーコン（ブロック） / Poitrine fumée | F39: =IF(COUNTIFS($C$3:C39,商品マスタ[[#This Row],[仕入先]],$E$3:E39,商品マスタ[[#This Row],[商品名]]) = 1, 1,0) | G39: =TEXT(SUMIF($C$3:C39,商品マスタ[[#This Row],[仕入先]],$F$3:F39), "0000") | I39: 150ｇ | J39: 5 | L39: 833 | M39: 45952 | N39: 1200 | O39: =IF(COUNT(商品マスタ[[#This Row],[参考上代 （税込)]]) > 0, (商品マスタ[[#This Row],[参考上代 （税込)]]-商品マスタ[[#This Row],[国内定価 （15％）]])/(商品マスタ[[#This Row],[参考上代 （税込)]]/1.08), "") | P39: 0.1 | Q39: =商品マスタ[[#This Row],[仕入 単価]]*商品マスタ[[#This Row],[標準国内送料率]] | S39: =IF(ISBLANK(商品マスタ[[#This Row],[実績 国内送料]]),商品マスタ[[#This Row],[標準国内送料]],) | T39: =商品マスタ[[#This Row],[仕入 単価]]+商品マスタ[[#This Row],[国内送料]] | U39: =ROUNDUP(商品マスタ[[#This Row],[仕入単価+国内送料]]/0.8,-1) | V39: =商品マスタ[[#This Row],[海外定価 （20％）]]-商品マスタ[[#This Row],[仕入単価+国内送料]] | W39: =ROUNDUP(商品マスタ[[#This Row],[仕入単価+国内送料]]/0.85,-1) | X39: =商品マスタ[[#This Row],[国内定価 （15％）]]-商品マスタ[[#This Row],[仕入単価+国内送料]] | Y39: 0.08 | Z39: 30日 | AA39: 10℃以下 | AB39: 5日 | AC39: 4580578380156 | AD39: 桜のチップでスモーク。熟成と燻煙で肉のうまみを凝縮したベーコン。パスタや煮込み料理に。 | AF39: 〇 | AG39: 2万円以上の注文で送料無料。
A40: 飲料アルコール | B40: ワイン | C40: シャルキュトリーアカイシ | D40: ="PRD_SNJ_"& _xlfn.XLOOKUP(商品マスタ[[#This Row],[仕入先]],テーブル1[仕入先名],テーブル1[仕入先コード],"XXX",0,1)& "_"& 商品マスタ[[#This Row],[シリアル]]& "_"& TEXT(COUNTIFS(商品マスタ!$C$3:C40,商品マスタ[[#This Row],[仕入先]],商品マスタ!$E$3:E40,商品マスタ[[#This Row],[商品名]]), "00") | E40: 鶏白レバーペースト/ Pâté de foie blond de volaille | F40: =IF(COUNTIFS($C$3:C40,商品マスタ[[#This Row],[仕入先]],$E$3:E40,商品マスタ[[#This Row],[商品名]]) = 1, 1,0) | G40: =TEXT(SUMIF($C$3:C40,商品マスタ[[#This Row],[仕入先]],$F$3:F40), "0000") | I40: 80g | J40: 5 | L40: 625 | M40: 45952 | N40: 900 | O40: =IF(COUNT(商品マスタ[[#This Row],[参考上代 （税込)]]) > 0, (商品マスタ[[#This Row],[参考上代 （税込)]]-商品マスタ[[#This Row],[国内定価 （15％）]])/(商品マスタ[[#This Row],[参考上代 （税込)]]/1.08), "") | P40: 0.1 | Q40: =商品マスタ[[#This Row],[仕入 単価]]*商品マスタ[[#This Row],[標準国内送料率]] | S40: =IF(ISBLANK(商品マスタ[[#This Row],[実績 国内送料]]),商品マスタ[[#This Row],[標準国内送料]],) | T40: =商品マスタ[[#This Row],[仕入 単価]]+商品マスタ[[#This Row],[国内送料]] | U40: =ROUNDUP(商品マスタ[[#This Row],[仕入単価+国内送料]]/0.8,-1) | V40: =商品マスタ[[#This Row],[海外定価 （20％）]]-商品マスタ[[#This Row],[仕入単価+国内送料]] | W40: =ROUNDUP(商品マスタ[[#This Row],[仕入単価+国内送料]]/0.85,-1) | X40: =商品マスタ[[#This Row],[国内定価 （15％）]]-商品マスタ[[#This Row],[仕入単価+国内送料]] | Y40: 0.08 | Z40: 30日 | AA40: 10℃以下 | AB40: 5日 | AC40: 4580578380194 | AD40: 貴重な鶏の〝フォアグラ〟をクリームと合わせてリッチな味わいのペーストの。スライスしたハード系のパンと一緒に。赤ワインによく合う人気の商品。 | AF40: 〇 | AG40: 2万円以上の注文で送料無料。
...

Sheet 案件番号採番
A1: ※灰色セルは自動入力
A2: ID | B2: 年 | C2: 月 | D2: 担当者 | E2: 支店 | F2: 顧客 | G2: 案件番号 | H2: 商品
A3: =ROW([1]!tbl_採番[[#This Row],[ID]])-2 | B3: 2026 | C3: 1 | D3: 杉田 | E3: 大阪 | F3: 日新堂株式会社 | G3: =IF(ISBLANK([1]!tbl_採番[[#This Row],[年]]),"",(RIGHT([1]!tbl_採番[[#This Row],[年]],2)&TEXT([1]!tbl_採番[[#This Row],[月]],"00")&"-1"&TEXT(COUNTIFS(B$3:B3,B3,C$3:C3,C3),"000")&"-"&_xlfn.XLOOKUP([1]!tbl_採番[[#This Row],[担当者]],[1]入力ルール用シート!$D$2:$D$8,[1]入力ルール用シート!$E$2:$E$8,"",0,1)&_xlfn.XLOOKUP([1]!tbl_採番[[#This Row],[支店]],[1]入力ルール用シート!$F$2:$F$3,[1]入力ルール用シート!$G$2:$G$3,"",0,1)))
A4: =ROW([1]!tbl_採番[[#This Row],[ID]])-2 | B4: 2026 | C4: 1 | D4: 杉田 | E4: 大阪 | F4: 日新堂株式会社 | G4: =IF(ISBLANK([1]!tbl_採番[[#This Row],[年]]),"",(RIGHT([1]!tbl_採番[[#This Row],[年]],2)&TEXT([1]!tbl_採番[[#This Row],[月]],"00")&"-1"&TEXT(COUNTIFS(B$3:B4,B4,C$3:C4,C4),"000")&"-"&_xlfn.XLOOKUP([1]!tbl_採番[[#This Row],[担当者]],[1]入力ルール用シート!$D$2:$D$8,[1]入力ルール用シート!$E$2:$E$8,"",0,1)&_xlfn.XLOOKUP([1]!tbl_採番[[#This Row],[支店]],[1]入力ルール用シート!$F$2:$F$3,[1]入力ルール用シート!$G$2:$G$3,"",0,1)))
A5: =ROW([1]!tbl_採番[[#This Row],[ID]])-2 | B5: 2026 | C5: 1 | D5: 永井 | E5: 大阪 | F5: オーセントホテルズ（楽水山） | G5: =IF(ISBLANK([1]!tbl_採番[[#This Row],[年]]),"",(RIGHT([1]!tbl_採番[[#This Row],[年]],2)&TEXT([1]!tbl_採番[[#This Row],[月]],"00")&"-1"&TEXT(COUNTIFS(B$3:B5,B5,C$3:C5,C5),"000")&"-"&_xlfn.XLOOKUP([1]!tbl_採番[[#This Row],[担当者]],[1]入力ルール用シート!$D$2:$D$8,[1]入力ルール用シート!$E$2:$E$8,"",0,1)&_xlfn.XLOOKUP([1]!tbl_採番[[#This Row],[支店]],[1]入力ルール用シート!$F$2:$F$3,[1]入力ルール用シート!$G$2:$G$3,"",0,1)))
A6: =ROW([1]!tbl_採番[[#This Row],[ID]])-2 | B6: 2026 | C6: 1 | D6: 杉田 | E6: 大阪 | F6: ホロニック（ガーデンシティクラブ大阪） | G6: =IF(ISBLANK([1]!tbl_採番[[#This Row],[年]]),"",(RIGHT([1]!tbl_採番[[#This Row],[年]],2)&TEXT([1]!tbl_採番[[#This Row],[月]],"00")&"-1"&TEXT(COUNTIFS(B$3:B6,B6,C$3:C6,C6),"000")&"-"&_xlfn.XLOOKUP([1]!tbl_採番[[#This Row],[担当者]],[1]入力ルール用シート!$D$2:$D$8,[1]入力ルール用シート!$E$2:$E$8,"",0,1)&_xlfn.XLOOKUP([1]!tbl_採番[[#This Row],[支店]],[1]入力ルール用シート!$F$2:$F$3,[1]入力ルール用シート!$G$2:$G$3,"",0,1)))
A7: =ROW([1]!tbl_採番[[#This Row],[ID]])-2 | B7: 2026 | C7: 1 | D7: 杉田 | E7: 大阪 | F7: 日新堂株式会社 | G7: =IF(ISBLANK([1]!tbl_採番[[#This Row],[年]]),"",(RIGHT([1]!tbl_採番[[#This Row],[年]],2)&TEXT([1]!tbl_採番[[#This Row],[月]],"00")&"-1"&TEXT(COUNTIFS(B$3:B7,B7,C$3:C7,C7),"000")&"-"&_xlfn.XLOOKUP([1]!tbl_採番[[#This Row],[担当者]],[1]入力ルール用シート!$D$2:$D$8,[1]入力ルール用シート!$E$2:$E$8,"",0,1)&_xlfn.XLOOKUP([1]!tbl_採番[[#This Row],[支店]],[1]入力ルール用シート!$F$2:$F$3,[1]入力ルール用シート!$G$2:$G$3,"",0,1)))
A8: =ROW([1]!tbl_採番[[#This Row],[ID]])-2 | B8: 2026 | C8: 1 | D8: 杉田 | E8: 大阪 | F8: 雲鶴 | G8: =IF(ISBLANK([1]!tbl_採番[[#This Row],[年]]),"",(RIGHT([1]!tbl_採番[[#This Row],[年]],2)&TEXT([1]!tbl_採番[[#This Row],[月]],"00")&"-1"&TEXT(COUNTIFS(B$3:B8,B8,C$3:C8,C8),"000")&"-"&_xlfn.XLOOKUP([1]!tbl_採番[[#This Row],[担当者]],[1]入力ルール用シート!$D$2:$D$8,[1]入力ルール用シート!$E$2:$E$8,"",0,1)&_xlfn.XLOOKUP([1]!tbl_採番[[#This Row],[支店]],[1]入力ルール用シート!$F$2:$F$3,[1]入力ルール用シート!$G$2:$G$3,"",0,1)))
A9: =ROW([1]!tbl_採番[[#This Row],[ID]])-2 | B9: 2026 | C9: 1 | D9: 杉田 | E9: 大阪 | F9: オーセントホテルズ株式会社 | G9: =IF(ISBLANK([1]!tbl_採番[[#This Row],[年]]),"",(RIGHT([1]!tbl_採番[[#This Row],[年]],2)&TEXT([1]!tbl_採番[[#This Row],[月]],"00")&"-1"&TEXT(COUNTIFS(B$3:B9,B9,C$3:C9,C9),"000")&"-"&_xlfn.XLOOKUP([1]!tbl_採番[[#This Row],[担当者]],[1]入力ルール用シート!$D$2:$D$8,[1]入力ルール用シート!$E$2:$E$8,"",0,1)&_xlfn.XLOOKUP([1]!tbl_採番[[#This Row],[支店]],[1]入力ルール用シート!$F$2:$F$3,[1]入力ルール用シート!$G$2:$G$3,"",0,1)))
A10: =ROW([1]!tbl_採番[[#This Row],[ID]])-2 | B10: 2026 | C10: 2 | D10: 永井 | E10: 大阪 | F10: フェリーサービス株式会社 | G10: =IF(ISBLANK([1]!tbl_採番[[#This Row],[年]]),"",(RIGHT([1]!tbl_採番[[#This Row],[年]],2)&TEXT([1]!tbl_採番[[#This Row],[月]],"00")&"-1"&TEXT(COUNTIFS(B$3:B10,B10,C$3:C10,C10),"000")&"-"&_xlfn.XLOOKUP([1]!tbl_採番[[#This Row],[担当者]],[1]入力ルール用シート!$D$2:$D$8,[1]入力ルール用シート!$E$2:$E$8,"",0,1)&_xlfn.XLOOKUP([1]!tbl_採番[[#This Row],[支店]],[1]入力ルール用シート!$F$2:$F$3,[1]入力ルール用シート!$G$2:$G$3,"",0,1)))
A11: =ROW([1]!tbl_採番[[#This Row],[ID]])-2 | B11: 2026 | C11: 2 | D11: 門永 | E11: 大阪 | F11: NISSHAビジネスサービス | G11: =IF(ISBLANK([1]!tbl_採番[[#This Row],[年]]),"",(RIGHT([1]!tbl_採番[[#This Row],[年]],2)&TEXT([1]!tbl_採番[[#This Row],[月]],"00")&"-1"&TEXT(COUNTIFS(B$3:B11,B11,C$3:C11,C11),"000")&"-"&_xlfn.XLOOKUP([1]!tbl_採番[[#This Row],[担当者]],[1]入力ルール用シート!$D$2:$D$8,[1]入力ルール用シート!$E$2:$E$8,"",0,1)&_xlfn.XLOOKUP([1]!tbl_採番[[#This Row],[支店]],[1]入力ルール用シート!$F$2:$F$3,[1]入力ルール用シート!$G$2:$G$3,"",0,1)))
A12: =ROW([1]!tbl_採番[[#This Row],[ID]])-2 | B12: 2026 | C12: 2 | D12: 杉田 | E12: 大阪 | F12: 日新堂株式会社 | G12: =IF(ISBLANK([1]!tbl_採番[[#This Row],[年]]),"",(RIGHT([1]!tbl_採番[[#This Row],[年]],2)&TEXT([1]!tbl_採番[[#This Row],[月]],"00")&"-1"&TEXT(COUNTIFS(B$3:B12,B12,C$3:C12,C12),"000")&"-"&_xlfn.XLOOKUP([1]!tbl_採番[[#This Row],[担当者]],[1]入力ルール用シート!$D$2:$D$8,[1]入力ルール用シート!$E$2:$E$8,"",0,1)&_xlfn.XLOOKUP([1]!tbl_採番[[#This Row],[支店]],[1]入力ルール用シート!$F$2:$F$3,[1]入力ルール用シート!$G$2:$G$3,"",0,1)))
A13: =ROW([1]!tbl_採番[[#This Row],[ID]])-2 | B13: 2026 | C13: 2 | D13: 杉田 | E13: 大阪 | F13: 日新堂株式会社 | G13: =IF(ISBLANK([1]!tbl_採番[[#This Row],[年]]),"",(RIGHT([1]!tbl_採番[[#This Row],[年]],2)&TEXT([1]!tbl_採番[[#This Row],[月]],"00")&"-1"&TEXT(COUNTIFS(B$3:B13,B13,C$3:C13,C13),"000")&"-"&_xlfn.XLOOKUP([1]!tbl_採番[[#This Row],[担当者]],[1]入力ルール用シート!$D$2:$D$8,[1]入力ルール用シート!$E$2:$E$8,"",0,1)&_xlfn.XLOOKUP([1]!tbl_採番[[#This Row],[支店]],[1]入力ルール用シート!$F$2:$F$3,[1]入力ルール用シート!$G$2:$G$3,"",0,1)))
